Workbook

Sheet Zeiterfassung
A1: Datum | B1: Aufgabe | C1: Arbeitszeit (Stunden)
A2: KW 26 (22.06.–28.06.2026) | C2: 16,00 Std.
A3: 23. Juni 2026 | B3: QR Code / Short.io: Ausarbeitung einer strukturierten Leistungsbeschreibung für die geplante Short.io-Anfrage einschließlich fachlicher Anforderungen, relevanter Rahmenbedingungen und prüffähiger Anfrageinhalte als Grundlage für die weitere Anbieterabstimmung. | C3: 1,20
A4: 24. Juni 2026 | B4: Studie 2027: Abstimmung mit Jule, Simone und Cathleen zur Konzeption und Einordnung der vier vorgesehenen Testvarianten; Klärung zentraler Anforderungen, Variantenlogik und nächster Schritte für die weitere Studienplanung. | C4: 1,00
A5: 24. Juni 2026 | B5: Studie 2027: Einarbeitung in Methodik und Studienunterlagen; Recherche und fachliche Einordnung der verwendeten Methode sowie Durcharbeitung vorhandener Präsentationsunterlagen zur Vorbereitung der weiteren konzeptionellen und inhaltlichen Ausarbeitung. | C5: 1,60
A6: 24. Juni 2026 | B6: Studie 2027: Erstellung und Strukturierung eines Briefings für Cathleen zur weiteren Bearbeitung der Präsentation, einschließlich Zusammenfassung relevanter Inhalte und Anforderungen für die nächste Ausarbeitungsschleife. | C6: 0,50
A7: 25. Juni 2026 | B7: Studie 2027: Finalisierung des Briefings für Cathleen sowie Ausarbeitung und Präzisierung von Textvorschlägen und Visualisierungsansätzen für die Studienpräsentation. | C7: 1,20
A8: 25. Juni 2026 | B8: Studie 2027: Vorbereitung und Formulierung der Anfrage zu POSTWURFSPEZIAL unter Berücksichtigung der für die Studienumsetzung relevanten Anforderungen und Abstimmungsbedarfe. | C8: 0,60
A9: 25. Juni 2026 | B9: Studie 2027: Durchführung einer Ist-/Soll-Analyse für das Studienmailing; Prüfung des Partnerfragebogens und der InDesign-Vorlagen sowie Bewertung möglicher Automatisierungsansätze einschließlich teambezogener Abstimmungen zu Umsetzbarkeit und Vorgehen. | C9: 2,15
A10: 25. Juni 2026 | B10: Studie 2027: Klärung des geplanten Pre-Test-Vorgehens mit dem Team, einschließlich Abstimmung offener Punkte und Einordnung der nächsten Schritte für die weitere Studienvorbereitung. | C10: 0,30
A11: 25. Juni 2026 | B11: Studie 2027: Einholung aktueller Statusinformationen und Aktualisierung der Arbeitspakete bis zum 03.07.; Strukturierung offener Punkte und Nachverfolgung relevanter Zuständigkeiten. | C11: 0,50
A12: 26. Juni 2026 | B12: Studie 2027: Erstellung eines Skripts und einer inhaltlichen Zusammenfassung als Testfassung für Jule und Simone, einschließlich Aufbereitung relevanter Punkte für Prüfung, Feedback und weitere Abstimmung. | C12: 1,55
A13: 26. Juni 2026 | B13: Studie 2027: Vor- und Nachbereitung der Abstimmung mit Christina einschließlich Terminabgleich, Strukturierung relevanter Inhalte und Ableitung nächster Schritte für die weitere Studien- und Präsentationsarbeit. | C13: 1,10
A14: 26. Juni 2026 | B14: Studie 2027: Abstimmung mit Lone und Lisa zum Pre-Test sowie zum Stand der bis Freitag vorgesehenen To-dos; Klärung offener Punkte, Zuständigkeiten und nächster Schritte. | C14: 0,70
... A18: 27. Juni 2026 | B18: Studie 2027: Zusammenfassung der Ergebnisse des Skripttests und Vorbereitung des nächsten Skripttests einschließlich Strukturierung offener Prüf- und Anpassungspunkte. | C18: 1,00
B19: Summe Stunden KW 26 | C19: 16,00
A21: KW 27 (29.06.–05.07.2026) | C21: 19,85 Std.
A22: 29. Juni 2026 | B22: Studie 2027: Rückmeldung an Christina mit Bitte um ein Angebot für das Neukundenmodul; Präzisierung des Abstimmungsbedarfs und Vorbereitung der weiteren Entscheidungsgrundlage. | C22: 0,20
A23: 29. Juni 2026 | B23: Studie 2027: Aktualisierung des Projektplans anhand der Rückmeldungen von Robert; Kommunikation neuer Aufgaben und erwarteter Outcomes an die Beteiligten sowie Beauftragung der benötigten InDesign-Lizenz. | C23: 0,80
A24: 29. Juni 2026 | B24: Studie 2027: Konzeption und Umsetzungsschritte für eine KI-gestützte Lösung zur Variantenaufbereitung und automatisierten Auswertung von Partnerdaten; Zusammenstellung relevanter Dokumente und Assets für den Testlauf sowie Prüfung des Fragebogens auf Struktur und Umsetzbarkeit. | C24: 3,80
A25: 29. Juni 2026 | B25: Studie 2027: Call mit Simone zur Erklärung des KI-gestützten Prozesses, Einführung in die InDesign-Anforderungen sowie Abstimmung zur Benennung der Felder und Befüllung der Excel-Vorlage. | C25: 1,00
A26: 30. Juni 2026 | B26: Studie 2027: Abstimmungen mit Jule, Cathleen und Simone zu aktuellen Herausforderungen, Statusständen und nächsten Schritten; ergänzende Rückmeldung an Christina. | C26: 1,20
A27: 30. Juni 2026 | B27: Studie 2027: Weiterarbeit an der KI-gestützten Lösung zur Variantenaufbereitung und automatisierten Auswertung von Partnerdaten; Weiterentwicklung des InDesign-Skripts für den nächsten Testlauf. | C27: 1,75
A28: 30. Juni 2026 | B28: Studie 2027: Review der von Cathleen überarbeiteten Präsentation; Prüfung inhaltlicher Anpassungen und Weitergabe relevanter Rückmeldungen für die weitere Bearbeitung. | C28: 0,60
A29: 1. Juli 2026 | B29: Studie 2027: Auswertung der Testvariante A; Anpassung des Skripts auf Basis der Testergebnisse sowie Abstimmungen und Status-Update zum weiteren Vorgehen. | C29: 2,75
A30: 2. Juli 2026 | B30: Studie 2027: Anpassung des Skripts anhand der Variablenliste für alle vier Varianten; Erweiterung um das Einlesen und Einspielen von Bildern sowie Definition und Kommunikation des nächsten Tests über alle vier Varianten. | C30: 2,15
A31: 2. Juli 2026 | B31: Studie 2027: Vorbereitung eines Ende-zu-Ende-Tests für Shape Labs einschließlich Aufbereitung der Daten, Erstellung des Skripts und Definition der Testmessung. | C31: 1,50
A32: 3. Juli 2026 | B32: Studie 2027: Abstimmung mit Simone zur Durchführung des Ende-zu-Ende-Tests und Klärung des weiteren Vorgehens. | C32: 0,25
A33: 3. Juli 2026 | B33: Studie 2027: Auswertung eines erneuten Skripttests; Anpassung des Skripts für Test 2 über alle Varianten mit Vorder- und Rückseite. | C33: 1,15
... A35: 3. Juli 2026 | B35: Studie 2027: Begleitung des Ende-zu-Ende-Tests einschließlich Auswertung des aktuellen Stands und Aufbereitung eines Status-Updates. | C35: 1,40
B36: Summe Stunden KW 27 | C36: 19,85
A38: Gesamtsumme KW 26 + KW 27 | C38: 35,85 Std.
A50: 46209 | D50: Debrief mit Simone und Jule | E50: 1
A51: 46209 | D51: Neues Testpaket anhand des Debriefings + JSON Builder Tool für Jule und Simone zum selbst Erstellen der JSONS zukünftig inklusive Checks und Email Oputpu | E51: 3.4
A52: 46210 | D52: Kommunikation der nächsten Schritte an Jule und Simone, Auswertung Zeiten des Testlaufs, Statusupodate Studie 2027 | E52: 1.45
A53: 46210 | D53: Arbeit am JSON Builder Tool (Fehlerbehebung, Weitere Prüfungen und Optisch hübscher) + Weitere Runde Skript Optimierung und neue Testrunde mit JSON Builder und optimierten Skript | E53: 2.75

Sheet Budgetübersicht
A1: Budgetübersicht Zeit
A3: Budget-Eingaben
A4: Monatsbudget (Std.) | B4: =IF(Einstellungen!B14="","",Einstellungen!B14)
A5: KW-Budget (Std.) | B5: =IF(Einstellungen!B15="","",Einstellungen!B15)
A7: Monat | B7: Gebucht (Std.) | C7: Budget (Std.) | D7: Offen (Std.)
A8: =DATE(2026,1,1) | B8: =SUMIFS(Datenbasis!$E$13:$E$211,Datenbasis!$A$13:$A$211,">="&A8,Datenbasis!$A$13:$A$211,"<"&EDATE(A8,1)) | C8: =IF(Einstellungen!$B$14="","",Einstellungen!$B$14) | D8: =IF(C8="","",C8-B8)
A9: =DATE(2026,2,1) | B9: =SUMIFS(Datenbasis!$E$13:$E$211,Datenbasis!$A$13:$A$211,">="&A9,Datenbasis!$A$13:$A$211,"<"&EDATE(A9,1)) | C9: =IF(Einstellungen!$B$14="","",Einstellungen!$B$14) | D9: =IF(C9="","",C9-B9)
A10: =DATE(2026,3,1) | B10: =SUMIFS(Datenbasis!$E$13:$E$211,Datenbasis!$A$13:$A$211,">="&A10,Datenbasis!$A$13:$A$211,"<"&EDATE(A10,1)) | C10: =IF(Einstellungen!$B$14="","",Einstellungen!$B$14) | D10: =IF(C10="","",C10-B10)
A11: =DATE(2026,4,1) | B11: =SUMIFS(Datenbasis!$E$13:$E$211,Datenbasis!$A$13:$A$211,">="&A11,Datenbasis!$A$13:$A$211,"<"&EDATE(A11,1)) | C11: =IF(Einstellungen!$B$14="","",Einstellungen!$B$14) | D11: =IF(C11="","",C11-B11)
A12: =DATE(2026,5,1) | B12: =SUMIFS(Datenbasis!$E$13:$E$211,Datenbasis!$A$13:$A$211,">="&A12,Datenbasis!$A$13:$A$211,"<"&EDATE(A12,1)) | C12: =IF(Einstellungen!$B$14="","",Einstellungen!$B$14) | D12: =IF(C12="","",C12-B12)
A13: =DATE(2026,6,1) | B13: =SUMIFS(Datenbasis!$E$13:$E$211,Datenbasis!$A$13:$A$211,">="&A13,Datenbasis!$A$13:$A$211,"<"&EDATE(A13,1)) | C13: =IF(Einstellungen!$B$14="","",Einstellungen!$B$14) | D13: =IF(C13="","",C13-B13)
A14: =DATE(2026,7,1) | B14: =SUMIFS(Datenbasis!$E$13:$E$211,Datenbasis!$A$13:$A$211,">="&A14,Datenbasis!$A$13:$A$211,"<"&EDATE(A14,1)) | C14: =IF(Einstellungen!$B$14="","",Einstellungen!$B$14) | D14: =IF(C14="","",C14-B14)
A15: =DATE(2026,8,1) | B15: =SUMIFS(Datenbasis!$E$13:$E$211,Datenbasis!$A$13:$A$211,">="&A15,Datenbasis!$A$13:$A$211,"<"&EDATE(A15,1)) | C15: =IF(Einstellungen!$B$14="","",Einstellungen!$B$14) | D15: =IF(C15="","",C15-B15)
A16: =DATE(2026,9,1) | B16: =SUMIFS(Datenbasis!$E$13:$E$211,Datenbasis!$A$13:$A$211,">="&A16,Datenbasis!$A$13:$A$211,"<"&EDATE(A16,1)) | C16: =IF(Einstellungen!$B$14="","",Einstellungen!$B$14) | D16: =IF(C16="","",C16-B16)
A17: =DATE(2026,10,1) | B17: =SUMIFS(Datenbasis!$E$13:$E$211,Datenbasis!$A$13:$A$211,">="&A17,Datenbasis!$A$13:$A$211,"<"&EDATE(A17,1)) | C17: =IF(Einstellungen!$B$14="","",Einstellungen!$B$14) | D17: =IF(C17="","",C17-B17)
A18: =DATE(2026,11,1) | B18: =SUMIFS(Datenbasis!$E$13:$E$211,Datenbasis!$A$13:$A$211,">="&A18,Datenbasis!$A$13:$A$211,"<"&EDATE(A18,1)) | C18: =IF(Einstellungen!$B$14="","",Einstellungen!$B$14) | D18: =IF(C18="","",C18-B18)
A19: =DATE(2026,12,1) | B19: =SUMIFS(Datenbasis!$E$13:$E$211,Datenbasis!$A$13:$A$211,">="&A19,Datenbasis!$A$13:$A$211,"<"&EDATE(A19,1)) | C19: =IF(Einstellungen!$B$14="","",Einstellungen!$B$14) | D19: =IF(C19="","",C19-B19)
A22: KW | B22: Gebucht (Std.) | C22: Budget (Std.) | D22: Offen (Std.)
A23: 1 | B23: =IF(SUMIFS(Datenbasis!$E$13:$E$211,Datenbasis!$H$13:$H$211,A23)=0,"",SUMIFS(Datenbasis!$E$13:$E$211,Datenbasis!$H$13:$H$211,A23)) | C23: =IF(OR(B23="",Einstellungen!$B$15=""),"",Einstellungen!$B$15) | D23: =IF(C23="","",C23-B23)
A24: 2 | B24: =IF(SUMIFS(Datenbasis!$E$13:$E$211,Datenbasis!$H$13:$H$211,A24)=0,"",SUMIFS(Datenbasis!$E$13:$E$211,Datenbasis!$H$13:$H$211,A24)) | C24: =IF(OR(B24="",Einstellungen!$B$15=""),"",Einstellungen!$B$15) | D24: =IF(C24="","",C24-B24)
A25: 3 | B25: =IF(SUMIFS(Datenbasis!$E$13:$E$211,Datenbasis!$H$13:$H$211,A25)=0,"",SUMIFS(Datenbasis!$E$13:$E$211,Datenbasis!$H$13:$H$211,A25)) | C25: =IF(OR(B25="",Einstellungen!$B$15=""),"",Einstellungen!$B$15) | D25: =IF(C25="","",C25-B25)
A26: 4 | B26: =IF(SUMIFS(Datenbasis!$E$13:$E$211,Datenbasis!$H$13:$H$211,A26)=0,"",SUMIFS(Datenbasis!$E$13:$E$211,Datenbasis!$H$13:$H$211,A26)) | C26: =IF(OR(B26="",Einstellungen!$B$15=""),"",Einstellungen!$B$15) | D26: =IF(C26="","",C26-B26)
A27: 5 | B27: =IF(SUMIFS(Datenbasis!$E$13:$E$211,Datenbasis!$H$13:$H$211,A27)=0,"",SUMIFS(Datenbasis!$E$13:$E$211,Datenbasis!$H$13:$H$211,A27)) | C27: =IF(OR(B27="",Einstellungen!$B$15=""),"",Einstellungen!$B$15) | D27: =IF(C27="","",C27-B27)
A28: 6 | B28: =IF(SUMIFS(Datenbasis!$E$13:$E$211,Datenbasis!$H$13:$H$211,A28)=0,"",SUMIFS(Datenbasis!$E$13:$E$211,Datenbasis!$H$13:$H$211,A28)) | C28: =IF(OR(B28="",Einstellungen!$B$15=""),"",Einstellungen!$B$15) | D28: =IF(C28="","",C28-B28)
A29: 7 | B29: =IF(SUMIFS(Datenbasis!$E$13:$E$211,Datenbasis!$H$13:$H$211,A29)=0,"",SUMIFS(Datenbasis!$E$13:$E$211,Datenbasis!$H$13:$H$211,A29)) | C29: =IF(OR(B29="",Einstellungen!$B$15=""),"",Einstellungen!$B$15) | D29: =IF(C29="","",C29-B29)
A30: 8 | B30: =IF(SUMIFS(Datenbasis!$E$13:$E$211,Datenbasis!$H$13:$H$211,A30)=0,"",SUMIFS(Datenbasis!$E$13:$E$211,Datenbasis!$H$13:$H$211,A30)) | C30: =IF(OR(B30="",Einstellungen!$B$15=""),"",Einstellungen!$B$15) | D30: =IF(C30="","",C30-B30)
A31: 9 | B31: =IF(SUMIFS(Datenbasis!$E$13:$E$211,Datenbasis!$H$13:$H$211,A31)=0,"",SUMIFS(Datenbasis!$E$13:$E$211,Datenbasis!$H$13:$H$211,A31)) | C31: =IF(OR(B31="",Einstellungen!$B$15=""),"",Einstellungen!$B$15) | D31: =IF(C31="","",C31-B31)
A32: 10 | B32: =IF(SUMIFS(Datenbasis!$E$13:$E$211,Datenbasis!$H$13:$H$211,A32)=0,"",SUMIFS(Datenbasis!$E$13:$E$211,Datenbasis!$H$13:$H$211,A32)) | C32: =IF(OR(B32="",Einstellungen!$B$15=""),"",Einstellungen!$B$15) | D32: =IF(C32="","",C32-B32)
A33: 11 | B33: =IF(SUMIFS(Datenbasis!$E$13:$E$211,Datenbasis!$H$13:$H$211,A33)=0,"",SUMIFS(Datenbasis!$E$13:$E$211,Datenbasis!$H$13:$H$211,A33)) | C33: =IF(OR(B33="",Einstellungen!$B$15=""),"",Einstellungen!$B$15) | D33: =IF(C33="","",C33-B33)
A34: 12 | B34: =IF(SUMIFS(Datenbasis!$E$13:$E$211,Datenbasis!$H$13:$H$211,A34)=0,"",SUMIFS(Datenbasis!$E$13:$E$211,Datenbasis!$H$13:$H$211,A34)) | C34: =IF(OR(B34="",Einstellungen!$B$15=""),"",Einstellungen!$B$15) | D34: =IF(C34="","",C34-B34)
... A75: 53 | B75: =IF(SUMIFS(Datenbasis!$E$13:$E$211,Datenbasis!$H$13:$H$211,A75)=0,"",SUMIFS(Datenbasis!$E$13:$E$211,Datenbasis!$H$13:$H$211,A75)) | C75: =IF(OR(B75="",Einstellungen!$B$15=""),"",Einstellungen!$B$15) | D75: =IF(C75="","",C75-B75)

Sheet Einstellungen
A1: Einstellungen
A2: Monat und Stundensatz hier ändern; alle Auswertungen und der Tätigkeitsschein greifen darauf zurück.
A4: Monat beginnt am | B4: 46174 | D4: Kategorie-Liste | E4: Status-Liste | F4: Monatslabel
A5: Stundensatz | B5: 85 | D5: Analyse / Recherche | E5: Initial | F5: =CHOOSE(MONTH(B4),"Januar","Februar","März","April","Mai","Juni","Juli","August","September","Oktober","November","Dezember")&" "&YEAR(B4)
A6: Auftraggeber | B6: Robert | D6: Technische Konzeption | E6: In Arbeit
A7: Auftragnehmer/in | B7: Maria | D7: Projektplanung | E7: Abgeschlossen
A8: Währung | B8: EUR | D8: Setup / Administration
A9: Max. Tracking-Zeilen | B9: 200 | D9: Umsetzung / Dokumentation
A10: Hinweis | B10: Zeiterfassung ist als Screenshot-Ansicht für Robert formatiert. Details/Kategorien liegen in der Datenbasis.
A11: Datei-Zweck | B11: Laufendes Time Tracking + monatlicher Tätigkeitsschein
A13: Budget-Eingaben
A14: Monatsbudget (Std.)
A15: KW-Budget (Std.)
A16: Hinweis | B16: Gelbe Zellen ausfüllen; Restbudget berechnet sich automatisch.

Sheet Datenbasis
A1: Datenbasis
A2: Interne Arbeitsdaten für Auswertung und Tätigkeitsschein. Roberts Screenshot wird aus dem Blatt Zeiterfassung erstellt.
A4: Monat | B4: Stundensatz | D4: Monatsstunden | E4: Monatsbetrag
A5: =Einstellungen!F5 | B5: =Einstellungen!B5 | D5: =SUMIFS(E13:E211,A13:A211,">="&Einstellungen!B4,A13:A211,"<"&DATE(YEAR(Einstellungen!B4),MONTH(Einstellungen!B4)+1,1)) | E5: =SUMIFS(G13:G211,A13:A211,">="&Einstellungen!B4,A13:A211,"<"&DATE(YEAR(Einstellungen!B4),MONTH(Einstellungen!B4)+1,1))
A12: Datum | B12: Bereich | C12: Aufgabe kurz | D12: Tätigkeit | E12: Zeit (Std.) | F12: Stundensatz | G12: Betrag | H12: KW | I12: Monat | J12: Kategorie | K12: Status
A13: 46190 | B13: QR Code | C13: Prozess-Refresh, Toolmarkt und Build-Option | D13: Einarbeitung in den bestehenden QR-Code-Prozess, Ableitung der Soll-Anforderungen an ein neues Tool, erste Marktanalyse geeigneter Anbieter sowie technische Machbarkeitsprüfung eines eigenen Builds. Ergebnis: Grundlage für die QR-Tool-Gegenüberstellung: Soll-Kriterien, Markt-/Eigenbau-Perspektive und erste technische Stack-Klarheit wurden herausgearbeitet. | E13: 3.15 | F13: =IF(A13="","",Einstellungen!$B$5) | G13: =IF(A13="","",E13*F13) | H13: =IF(A13="","",ISOWEEKNUM(A13)) | I13: =IF(A13="","",TEXT(A13,"[$-de-DE]MMMM YYYY")) | J13: Analyse / Recherche | K13: Abgeschlossen
A14: 46191 | B14: Technisches Setup | C14: Accounts, Mail und Arbeitsumgebung | D14: Einrichtung und Prüfung der benötigten Accounts/Mail-Zugänge sowie kurze Orientierung in vorhandenen technischen Unterlagen und Arbeitsständen. Ergebnis: Reduziert Reibung im Folgeprozess und stellt sicher, dass weitere Analyse/Umsetzung ohne Zugriffshürden starten kann. | E14: 0.75 | F14: =IF(A14="","",Einstellungen!$B$5) | G14: =IF(A14="","",E14*F14) | H14: =IF(A14="","",ISOWEEKNUM(A14)) | I14: =IF(A14="","",TEXT(A14,"[$-de-DE]MMMM YYYY")) | J14: Setup / Administration | K14: Abgeschlossen
A15: 46191 | B15: QR Code | C15: Technisches Setup und Stack-Vorauswahl | D15: Verfeinerung des technischen Setups, Recherche möglicher Stack-Varianten und Eingrenzung der sinnvollsten Tool-/Build-Richtung. Ergebnis: Verdichtet die offenen Optionen technisch: Stack-Richtung, Toolanforderungen und Build-Risiken wurden so geklärt, dass die Gegenüberstellung belastbarer wird. | E15: 1.5 | F15: =IF(A15="","",Einstellungen!$B$5) | G15: =IF(A15="","",E15*F15) | H15: =IF(A15="","",ISOWEEKNUM(A15)) | I15: =IF(A15="","",TEXT(A15,"[$-de-DE]MMMM YYYY")) | J15: Technische Konzeption | K15: Abgeschlossen
A16: 46191 | B16: Asana / Monday | C16: Projektplan Migration Monday zu Asana | D16: Aufsetzen eines ersten Projektplan-Rahmens für die Ablösung von Monday durch Asana inklusive erster Sichtung der Asana Features. | E16: 0.5 | F16: =IF(A16="","",Einstellungen!$B$5) | G16: =IF(A16="","",E16*F16) | H16: =IF(A16="","",ISOWEEKNUM(A16)) | I16: =IF(A16="","",TEXT(A16,"[$-de-DE]MMMM YYYY")) | J16: Projektplanung | K16: Initial
A17: 46192 | B17: Asana / Monday | C17: Board- und Prozessanalyse | D17: Analyse vorhandener Monday-Boards und Prozesse mit Blick auf Migrationsrelevanz, Struktur, Dubletten und notwendige Übertragungslogik. Ergebnis: Identifiziert, was wirklich migriert werden muss und wo Prozessvereinfachung möglich ist, statt bestehende Komplexität ungeprüft nach Asana zu kopieren. | E17: 1.15 | F17: =IF(A17="","",Einstellungen!$B$5) | G17: =IF(A17="","",E17*F17) | H17: =IF(A17="","",ISOWEEKNUM(A17)) | I17: =IF(A17="","",TEXT(A17,"[$-de-DE]MMMM YYYY")) | J17: Analyse / Recherche | K17: Initial
A18: 46193 | B18: QR Code | C18: Toolvergleich und Build-Abgleich | D18: Detaillierte Analyse ausgewählter markttauglicher Tools und strukturierter Abgleich der Ergebnisse mit den Anforderungen an einen möglichen eigenen Build. Ergebnis: CMC_QR_Tool_Gegenueberstellung.xlsx mit Entscheidungsmatrix, Annahmen, Kurzfazit und nächsten Schritten; ergänzt durch Klarheit zum technischen Stack. | E18: 2.75 | F18: =IF(A18="","",Einstellungen!$B$5) | G18: =IF(A18="","",E18*F18) | H18: =IF(A18="","",ISOWEEKNUM(A18)) | I18: =IF(A18="","",TEXT(A18,"[$-de-DE]MMMM YYYY")) | J18: Analyse / Recherche | K18: Abgeschlossen
A19: 46194 | B19: QR Code | C19: Gegenüberstellung prüfen, ergänzen und aufbereiten | D19: Durchsicht der QR-Tool-Gegenüberstellung, Ergänzung offener Punkte und Aufbereitung der Inhalte für eine verständliche Entscheidungsgrundlage. Ergebnis: Die Gegenüberstellung ist für Robert klarer nutzbar: Bewertung, Annahmen, Risiken und nächste Schritte sind konsistenter herausgearbeitet. | E19: 0.5 | F19: =IF(A19="","",Einstellungen!$B$5) | G19: =IF(A19="","",E19*F19) | H19: =IF(A19="","",ISOWEEKNUM(A19)) | I19: =IF(A19="","",TEXT(A19,"[$-de-DE]MMMM YYYY")) | J19: Analyse / Recherche | K19: Abgeschlossen
A20: 46196 | B20: QR Code | C20: Leistungsbeschreibung Short.io-Anfrage | D20: Ausarbeitung einer strukturierten Leistungsbeschreibung für die geplante Short.io-Anfrage einschließlich fachlicher Anforderungen, relevanter Rahmenbedingungen und prüffähiger Anfrageinhalte als Grundlage für die weitere Anbieterabstimmung. | E20: 1.2 | F20: =IF(A20="","",Einstellungen!$B$5) | G20: =IF(A20="","",E20*F20) | H20: =IF(A20="","",ISOWEEKNUM(A20)) | I20: =IF(A20="","",TEXT(A20,"[$-de-DE]MMMM YYYY"))
A21: 46197 | B21: Studie 2027 | C21: Abstimmung Testvarianten Studienkonzept | D21: Abstimmung mit Jule, Simone und Cathleen zur Konzeption und Einordnung der vier vorgesehenen Testvarianten; Klärung zentraler Anforderungen, Variantenlogik und nächster Schritte für die weitere Studienplanung. | E21: 1 | F21: =IF(A21="","",Einstellungen!$B$5) | G21: =IF(A21="","",E21*F21) | H21: =IF(A21="","",ISOWEEKNUM(A21)) | I21: =IF(A21="","",TEXT(A21,"[$-de-DE]MMMM YYYY"))
A22: 46197 | B22: Studie 2027 | C22: Einarbeitung Methodik und Studienunterlagen | D22: Einarbeitung in das Studienthema, Recherche und fachliche Einordnung der verwendeten Methoden sowie Durcharbeitung der vorhandenen Präsentationsunterlagen zur Vorbereitung der weiteren konzeptionellen und inhaltlichen Ausarbeitung. | E22: 1.6 | F22: =IF(A22="","",Einstellungen!$B$5) | G22: =IF(A22="","",E22*F22) | H22: =IF(A22="","",ISOWEEKNUM(A22)) | I22: =IF(A22="","",TEXT(A22,"[$-de-DE]MMMM YYYY"))
A23: 46197 | B23: Studie 2027 | C23: Briefing Präsentationsausarbeitung | D23: Erstellung und Strukturierung eines Briefings für Cathleen zur weiteren Bearbeitung der Präsentation, inklusive Zusammenfassung relevanter Inhalte und Anforderungen für die nächste Ausarbeitungsschleife. | E23: 0.5 | F23: =IF(A23="","",Einstellungen!$B$5) | G23: =IF(A23="","",E23*F23) | H23: =IF(A23="","",ISOWEEKNUM(A23)) | I23: =IF(A23="","",TEXT(A23,"[$-de-DE]MMMM YYYY"))
A24: 46198 | B24: Studie 2027 | C24: Finalisierung Briefing und Visualisierungstexte | D24: Finalisierung des Briefings für Cathleen sowie Ausarbeitung und Präzisierung von Textvorschlägen und Visualisierungsansätzen für die Studienpräsentation. | E24: 1.2 | F24: =IF(A24="","",Einstellungen!$B$5) | G24: =IF(A24="","",E24*F24) | H24: =IF(A24="","",ISOWEEKNUM(A24)) | I24: =IF(A24="","",TEXT(A24,"[$-de-DE]MMMM YYYY"))
A25: 46198 | B25: Studie 2027 | C25: Anfrage POSTWURFSPEZIAL | D25: Vorbereitung und Formulierung der Anfrage zu POSTWURFSPEZIAL unter Berücksichtigung der für die Studienumsetzung relevanten Anforderungen und Abstimmungsbedarfe. | E25: 0.6 | F25: =IF(A25="","",Einstellungen!$B$5) | G25: =IF(A25="","",E25*F25) | H25: =IF(A25="","",ISOWEEKNUM(A25)) | I25: =IF(A25="","",TEXT(A25,"[$-de-DE]MMMM YYYY"))
A26: 46198 | B26: Studie 2027 | C26: Ist-/Soll-Analyse Studienmailing | D26: Durchführung einer Ist-/Soll-Analyse für die Erstellung des Studienmailings; Prüfung des Partnerfragebogens und der InDesign-Vorlagen sowie Bewertung möglicher Automatisierungsansätze einschließlich teambezogener Abstimmungen zu Umsetzbarkeit und Vorgehen. | E26: 2.15 | F26: =IF(A26="","",Einstellungen!$B$5) | G26: =IF(A26="","",E26*F26) | H26: =IF(A26="","",ISOWEEKNUM(A26)) | I26: =IF(A26="","",TEXT(A26,"[$-de-DE]MMMM YYYY"))
A27: 46198 | B27: Studie 2027 | C27: Klärung Pre-Test-Vorgehen | D27: Klärung des geplanten Pre-Test-Vorgehens mit dem Team, einschließlich Abstimmung offener Punkte und Einordnung der nächsten Schritte für die weitere Studienvorbereitung. | E27: 0.3 | F27: =IF(A27="","",Einstellungen!$B$5) | G27: =IF(A27="","",E27*F27) | H27: =IF(A27="","",ISOWEEKNUM(A27)) | I27: =IF(A27="","",TEXT(A27,"[$-de-DE]MMMM YYYY"))
A28: 46198 | B28: Studie 2027 | C28: Statusabfrage und Arbeitspaket-Update | D28: Einholung aktueller Statusinformationen und Aktualisierung der Arbeitspakete bis zum 03.07.; Strukturierung der offenen Punkte und Nachverfolgung relevanter Zuständigkeiten. | E28: 0.5 | F28: =IF(A28="","",Einstellungen!$B$5) | G28: =IF(A28="","",E28*F28) | H28: =IF(A28="","",ISOWEEKNUM(A28)) | I28: =IF(A28="","",TEXT(A28,"[$-de-DE]MMMM YYYY"))
A29: 46199 | B29: Studie 2027 | C29: Testskript und Zusammenfassung | D29: Erstellung eines Skripts und Zusammenfassung der Inhalte als Testfassung für Jule und Simone, einschließlich Aufbereitung der relevanten Punkte für Prüfung, Feedback und weitere Abstimmung. | E29: 1.55 | F29: =IF(A29="","",Einstellungen!$B$5) | G29: =IF(A29="","",E29*F29) | H29: =IF(A29="","",ISOWEEKNUM(A29)) | I29: =IF(A29="","",TEXT(A29,"[$-de-DE]MMMM YYYY"))
A30: 46199 | B30: Studie 2027 | C30: Vor-/Nachbereitung Christina-Abstimmung | D30: Vor- und Nachbereitung der Abstimmung mit Christina einschließlich Terminabgleich, Strukturierung relevanter Inhalte und Ableitung der nächsten Schritte für die weitere Studien- und Präsentationsarbeit. | E30: 1.1 | F30: =IF(A30="","",Einstellungen!$B$5) | G30: =IF(A30="","",E30*F30) | H30: =IF(A30="","",ISOWEEKNUM(A30)) | I30: =IF(A30="","",TEXT(A30,"[$-de-DE]MMMM YYYY"))
A31: 46199 | B31: Studie 2027 | C31: Pre-Test-Abstimmung Lone/Lisa | D31: Abstimmung mit Lone und Lisa zum Pre-Test sowie zum Stand der bis Freitag vorgesehenen To-dos; Klärung offener Punkte, Zuständigkeiten und nächster Schritte. | E31: 0.7 | F31: =IF(A31="","",Einstellungen!$B$5) | G31: =IF(A31="","",E31*F31) | H31: =IF(A31="","",ISOWEEKNUM(A31)) | I31: =IF(A31="","",TEXT(A31,"[$-de-DE]MMMM YYYY"))
... A42: 46203 | B42: Studie 2027 | C42: Review und Weitergabe Präsentation | D42: Review der von Cathleen überarbeiteten Präsentation; Prüfung der inhaltlichen Anpassungen und Weitergabe relevanter Rückmeldungen für die weitere Bearbeitung. | E42: 0.6 | F42: =IF(A42="","",Einstellungen!$B$5) | G42: =IF(A42="","",E42*F42) | H42: =IF(A42="","",ISOWEEKNUM(A42)) | I42: =IF(A42="","",TEXT(A42,"[$-de-DE]MMMM YYYY"))
A43: 46204 | B43: Studie 2027 | D43: Auswertung Test A Variante + Anpassung Kript + Absprachen und Statusupdate | E43: 2.75 | F43: =IF(A43="","",Einstellungen!$B$5) | G43: =IF(A43="","",E43*F43) | H43: =IF(A43="","",ISOWEEKNUM(A43)) | I43: =IF(A43="","",TEXT(A43,"[$-de-DE]MMMM YYYY"))
A44: 46205 | B44: Studie 2027 | D44: Anpassung des Skriptes anhand der Variablen Liste für alle 4 Varianten + Anpassung, dass Bilder eingelesen und eingespielt werden + Definition und Kommunikation des nächsten Test für alle 4 Varianten | E44: 2.15 | F44: =IF(A44="","",Einstellungen!$B$5) | G44: =IF(A44="","",E44*F44) | H44: =IF(A44="","",ISOWEEKNUM(A44)) | I44: =IF(A44="","",TEXT(A44,"[$-de-DE]MMMM YYYY"))
A45: 46205 | B45: Studie 2027 | D45: Vorbereitung Ende zu Ende Test für Shabe Labs mit aufbereitung der Daten, Erstellen des Skriptes und Definiton der Testmessung | E45: 1.5 | F45: =IF(A45="","",Einstellungen!$B$5) | G45: =IF(A45="","",E45*F45) | H45: =IF(A45="","",ISOWEEKNUM(A45)) | I45: =IF(A45="","",TEXT(A45,"[$-de-DE]MMMM YYYY"))
A46: 46206 | B46: Studie 2027 | D46: Absprache Simone Durchführung End zu Ende Test | E46: 0.25 | F46: =IF(A46="","",Einstellungen!$B$5) | G46: =IF(A46="","",E46*F46) | H46: =IF(A46="","",ISOWEEKNUM(A46)) | I46: =IF(A46="","",TEXT(A46,"[$-de-DE]MMMM YYYY"))
A47: 46206 | B47: Studie 2027 | D47: Auswertung erneuter Skripttest + Anpassung Skript für Test 2 alle Varianten mit Vorder und Rückseite | E47: 1.15 | F47: =IF(A47="","",Einstellungen!$B$5) | G47: =IF(A47="","",E47*F47) | H47: =IF(A47="","",ISOWEEKNUM(A47)) | I47: =IF(A47="","",TEXT(A47,"[$-de-DE]MMMM YYYY"))
A48: 46206 | B48: Studie 2027 | D48: Auswertung erneuter Skripttest 2 + Anpassung Skript + Anpassung Shape Labs Testpaket | E48: 1.3 | F48: =IF(A48="","",Einstellungen!$B$5) | G48: =IF(A48="","",E48*F48) | H48: =IF(A48="","",ISOWEEKNUM(A48)) | I48: =IF(A48="","",TEXT(A48,"[$-de-DE]MMMM YYYY"))
A49: 46206 | B49: Studie 2027 | D49: Begleitung End zu Ende Test mit Auswertung des Standes und Statusupdate | E49: 1.4 | F49: =IF(A49="","",Einstellungen!$B$5) | G49: =IF(A49="","",E49*F49) | H49: =IF(A49="","",ISOWEEKNUM(A49)) | I49: =IF(A49="","",TEXT(A49,"[$-de-DE]MMMM YYYY"))
A50: 46209 | B50: Studie 2027 | D50: Debrief mit Simone und Jule | E50: 1 | F50: =IF(A50="","",Einstellungen!$B$5) | G50: =IF(A50="","",E50*F50) | H50: =IF(A50="","",ISOWEEKNUM(A50)) | I50: =IF(A50="","",TEXT(A50,"[$-de-DE]MMMM YYYY"))
A51: 46209 | B51: Studie 2027 | D51: Neues Testpaket anhand des Debriefings + JSON Builder Tool für Jule und Simone zum selbst Erstellen der JSONS zukünftig inklusive Checks und Email Oputpu | E51: 3.4 | F51: =IF(A51="","",Einstellungen!$B$5) | G51: =IF(A51="","",E51*F51) | H51: =IF(A51="","",ISOWEEKNUM(A51)) | I51: =IF(A51="","",TEXT(A51,"[$-de-DE]MMMM YYYY"))
A52: 46210 | B52: Studie 2027 | D52: Kommunikation der nächsten Schritte an Jule und Simone, Auswertung Zeiten des Testlaufs, Statusupodate Studie 2027 | E52: 1.45 | F52: =IF(A52="","",Einstellungen!$B$5) | G52: =IF(A52="","",E52*F52) | H52: =IF(A52="","",ISOWEEKNUM(A52)) | I52: =IF(A52="","",TEXT(A52,"[$-de-DE]MMMM YYYY"))
A53: 46210 | B53: Studie 2027 | D53: Arbeit am JSON Builder Tool (Fehlerbehebung, Weitere Prüfungen und Optisch hübscher) + Weitere Runde Skript Optimierung und neue Testrunde mit JSON Builder und optimierten Skript | E53: 2.75 | F53: =IF(A53="","",Einstellungen!$B$5) | G53: =IF(A53="","",E53*F53) | H53: =IF(A53="","",ISOWEEKNUM(A53)) | I53: =IF(A53="","",TEXT(A53,"[$-de-DE]MMMM YYYY"))
F54: =IF(A54="","",Einstellungen!$B$5) | G54: =IF(A54="","",E54*F54) | H54: =IF(A54="","",ISOWEEKNUM(A54)) | I54: =IF(A54="","",TEXT(A54,"[$-de-DE]MMMM YYYY"))
F55: =IF(A55="","",Einstellungen!$B$5) | G55: =IF(A55="","",E55*F55) | H55: =IF(A55="","",ISOWEEKNUM(A55)) | I55: =IF(A55="","",TEXT(A55,"[$-de-DE]MMMM YYYY"))
F56: =IF(A56="","",Einstellungen!$B$5) | G56: =IF(A56="","",E56*F56) | H56: =IF(A56="","",ISOWEEKNUM(A56)) | I56: =IF(A56="","",TEXT(A56,"[$-de-DE]MMMM YYYY"))
F57: =IF(A57="","",Einstellungen!$B$5) | G57: =IF(A57="","",E57*F57) | H57: =IF(A57="","",ISOWEEKNUM(A57)) | I57: =IF(A57="","",TEXT(A57,"[$-de-DE]MMMM YYYY"))
...

Sheet Auswertung
A1: Auswertung
A2: Kurzer Plausibilitätscheck und Monatsübersicht aus der Zeiterfassung.
A4: Monat | B4: =Einstellungen!F5 | D4: Kategorie | E4: Stunden | F4: Anteil
A5: Gesamtstunden | B5: =Datenbasis!D5 | D5: Analyse / Recherche | E5: =SUMIFS(Datenbasis!$E$13:$E$211,Datenbasis!$J$13:$J$211,D5,Datenbasis!$A$13:$A$211,">="&Einstellungen!$B$4,Datenbasis!$A$13:$A$211,"<"&DATE(YEAR(Einstellungen!$B$4),MONTH(Einstellungen!$B$4)+1,1)) | F5: =IF($B$5=0,0,E5/$B$5)
A6: Betrag | B6: =Datenbasis!E5 | D6: Technische Konzeption | E6: =SUMIFS(Datenbasis!$E$13:$E$211,Datenbasis!$J$13:$J$211,D6,Datenbasis!$A$13:$A$211,">="&Einstellungen!$B$4,Datenbasis!$A$13:$A$211,"<"&DATE(YEAR(Einstellungen!$B$4),MONTH(Einstellungen!$B$4)+1,1)) | F6: =IF($B$5=0,0,E6/$B$5)
D7: Projektplanung | E7: =SUMIFS(Datenbasis!$E$13:$E$211,Datenbasis!$J$13:$J$211,D7,Datenbasis!$A$13:$A$211,">="&Einstellungen!$B$4,Datenbasis!$A$13:$A$211,"<"&DATE(YEAR(Einstellungen!$B$4),MONTH(Einstellungen!$B$4)+1,1)) | F7: =IF($B$5=0,0,E7/$B$5)
D8: Setup / Administration | E8: =SUMIFS(Datenbasis!$E$13:$E$211,Datenbasis!$J$13:$J$211,D8,Datenbasis!$A$13:$A$211,">="&Einstellungen!$B$4,Datenbasis!$A$13:$A$211,"<"&DATE(YEAR(Einstellungen!$B$4),MONTH(Einstellungen!$B$4)+1,1)) | F8: =IF($B$5=0,0,E8/$B$5)
D9: Umsetzung / Dokumentation | E9: =SUMIFS(Datenbasis!$E$13:$E$211,Datenbasis!$J$13:$J$211,D9,Datenbasis!$A$13:$A$211,">="&Einstellungen!$B$4,Datenbasis!$A$13:$A$211,"<"&DATE(YEAR(Einstellungen!$B$4),MONTH(Einstellungen!$B$4)+1,1)) | F9: =IF($B$5=0,0,E9/$B$5)
A11: Schonungslos ehrlicher Check
A12: Gesamteindruck | B12: 10,30 Stunden für Startwoche/Analysephase sind plausibel. Der QR-Code-Anteil ist durch ein konkretes Ergebnis belegt: CMC_QR_Tool_Gegenueberstellung.xlsx plus technische Stack-Klarheit.
A13: QR-Code-Anteil | B13: 7,90 Stunden QR-Code sind mit diesem Output gut begründbar: Entscheidungsmatrix, Eigenbau-vs.-Markttool-Abgleich, Volumenannahmen, Risiken, Kurzfazit, Ergänzungen und nächste Schritte sind verwertbarer Mehrwert.
A14: Asana/Monday | B14: 1,65 Stunden sind für eine echte Migration zu wenig, aber als erster Projektplan plus Sichtung plausibel. Bitte nicht als vollständige Migrationsanalyse verkaufen.
A15: Setup-Zeit | B15: 0,75 Stunden für Accounts/Mail ist normal und unkritisch, sollte aber nicht größer werden, wenn kein technisches Problem dahintersteht.
A16: Empfehlung | B16: Für künftige Einträge immer ein Ergebnis ergänzen: Entscheidung, verworfene Option, Nächstes To-do, Risiko oder Vereinfachung. Dann liest Robert Mehrwert statt nur Arbeitszeit.
A19: KW | B19: Stunden | C19: Betrag | D19: Hinweis
A20: 25 | B20: =SUMIFS(Datenbasis!$E$13:$E$211,Datenbasis!$H$13:$H$211,A20,Datenbasis!$A$13:$A$211,">="&Einstellungen!$B$4,Datenbasis!$A$13:$A$211,"<"&DATE(YEAR(Einstellungen!$B$4),MONTH(Einstellungen!$B$4)+1,1)) | C20: =SUMIFS(Datenbasis!$G$13:$G$211,Datenbasis!$H$13:$H$211,A20,Datenbasis!$A$13:$A$211,">="&Einstellungen!$B$4,Datenbasis!$A$13:$A$211,"<"&DATE(YEAR(Einstellungen!$B$4),MONTH(Einstellungen!$B$4)+1,1)) | D20: =IF(B20=0,"",IF(B20<2,"kleiner Block / Kontextaufbau",IF(B20>8,"hoher Wochenblock - Output sichtbar machen","plausibler Wochenblock")))
A21: 26 | B21: =SUMIFS(Datenbasis!$E$13:$E$211,Datenbasis!$H$13:$H$211,A21,Datenbasis!$A$13:$A$211,">="&Einstellungen!$B$4,Datenbasis!$A$13:$A$211,"<"&DATE(YEAR(Einstellungen!$B$4),MONTH(Einstellungen!$B$4)+1,1)) | C21: =SUMIFS(Datenbasis!$G$13:$G$211,Datenbasis!$H$13:$H$211,A21,Datenbasis!$A$13:$A$211,">="&Einstellungen!$B$4,Datenbasis!$A$13:$A$211,"<"&DATE(YEAR(Einstellungen!$B$4),MONTH(Einstellungen!$B$4)+1,1)) | D21: =IF(B21=0,"",IF(B21<2,"kleiner Block / Kontextaufbau",IF(B21>8,"hoher Wochenblock - Output sichtbar machen","plausibler Wochenblock")))
A22: 27 | B22: =SUMIFS(Datenbasis!$E$13:$E$211,Datenbasis!$H$13:$H$211,A22,Datenbasis!$A$13:$A$211,">="&Einstellungen!$B$4,Datenbasis!$A$13:$A$211,"<"&DATE(YEAR(Einstellungen!$B$4),MONTH(Einstellungen!$B$4)+1,1)) | C22: =SUMIFS(Datenbasis!$G$13:$G$211,Datenbasis!$H$13:$H$211,A22,Datenbasis!$A$13:$A$211,">="&Einstellungen!$B$4,Datenbasis!$A$13:$A$211,"<"&DATE(YEAR(Einstellungen!$B$4),MONTH(Einstellungen!$B$4)+1,1)) | D22: =IF(B22=0,"",IF(B22<2,"kleiner Block / Kontextaufbau",IF(B22>8,"hoher Wochenblock - Output sichtbar machen","plausibler Wochenblock")))
A23: 28 | B23: =SUMIFS(Datenbasis!$E$13:$E$211,Datenbasis!$H$13:$H$211,A23,Datenbasis!$A$13:$A$211,">="&Einstellungen!$B$4,Datenbasis!$A$13:$A$211,"<"&DATE(YEAR(Einstellungen!$B$4),MONTH(Einstellungen!$B$4)+1,1)) | C23: =SUMIFS(Datenbasis!$G$13:$G$211,Datenbasis!$H$13:$H$211,A23,Datenbasis!$A$13:$A$211,">="&Einstellungen!$B$4,Datenbasis!$A$13:$A$211,"<"&DATE(YEAR(Einstellungen!$B$4),MONTH(Einstellungen!$B$4)+1,1)) | D23: =IF(B23=0,"",IF(B23<2,"kleiner Block / Kontextaufbau",IF(B23>8,"hoher Wochenblock - Output sichtbar machen","plausibler Wochenblock")))
A24: 29 | B24: =SUMIFS(Datenbasis!$E$13:$E$211,Datenbasis!$H$13:$H$211,A24,Datenbasis!$A$13:$A$211,">="&Einstellungen!$B$4,Datenbasis!$A$13:$A$211,"<"&DATE(YEAR(Einstellungen!$B$4),MONTH(Einstellungen!$B$4)+1,1)) | C24: =SUMIFS(Datenbasis!$G$13:$G$211,Datenbasis!$H$13:$H$211,A24,Datenbasis!$A$13:$A$211,">="&Einstellungen!$B$4,Datenbasis!$A$13:$A$211,"<"&DATE(YEAR(Einstellungen!$B$4),MONTH(Einstellungen!$B$4)+1,1)) | D24: =IF(B24=0,"",IF(B24<2,"kleiner Block / Kontextaufbau",IF(B24>8,"hoher Wochenblock - Output sichtbar machen","plausibler Wochenblock")))
A25: 30 | B25: =SUMIFS(Datenbasis!$E$13:$E$211,Datenbasis!$H$13:$H$211,A25,Datenbasis!$A$13:$A$211,">="&Einstellungen!$B$4,Datenbasis!$A$13:$A$211,"<"&DATE(YEAR(Einstellungen!$B$4),MONTH(Einstellungen!$B$4)+1,1)) | C25: =SUMIFS(Datenbasis!$G$13:$G$211,Datenbasis!$H$13:$H$211,A25,Datenbasis!$A$13:$A$211,">="&Einstellungen!$B$4,Datenbasis!$A$13:$A$211,"<"&DATE(YEAR(Einstellungen!$B$4),MONTH(Einstellungen!$B$4)+1,1)) | D25: =IF(B25=0,"",IF(B25<2,"kleiner Block / Kontextaufbau",IF(B25>8,"hoher Wochenblock - Output sichtbar machen","plausibler Wochenblock")))
A26: 31 | B26: =SUMIFS(Datenbasis!$E$13:$E$211,Datenbasis!$H$13:$H$211,A26,Datenbasis!$A$13:$A$211,">="&Einstellungen!$B$4,Datenbasis!$A$13:$A$211,"<"&DATE(YEAR(Einstellungen!$B$4),MONTH(Einstellungen!$B$4)+1,1)) | C26: =SUMIFS(Datenbasis!$G$13:$G$211,Datenbasis!$H$13:$H$211,A26,Datenbasis!$A$13:$A$211,">="&Einstellungen!$B$4,Datenbasis!$A$13:$A$211,"<"&DATE(YEAR(Einstellungen!$B$4),MONTH(Einstellungen!$B$4)+1,1)) | D26: =IF(B26=0,"",IF(B26<2,"kleiner Block / Kontextaufbau",IF(B26>8,"hoher Wochenblock - Output sichtbar machen","plausibler Wochenblock")))
A27: 32 | B27: =SUMIFS(Datenbasis!$E$13:$E$211,Datenbasis!$H$13:$H$211,A27,Datenbasis!$A$13:$A$211,">="&Einstellungen!$B$4,Datenbasis!$A$13:$A$211,"<"&DATE(YEAR(Einstellungen!$B$4),MONTH(Einstellungen!$B$4)+1,1)) | C27: =SUMIFS(Datenbasis!$G$13:$G$211,Datenbasis!$H$13:$H$211,A27,Datenbasis!$A$13:$A$211,">="&Einstellungen!$B$4,Datenbasis!$A$13:$A$211,"<"&DATE(YEAR(Einstellungen!$B$4),MONTH(Einstellungen!$B$4)+1,1)) | D27: =IF(B27=0,"",IF(B27<2,"kleiner Block / Kontextaufbau",IF(B27>8,"hoher Wochenblock - Output sichtbar machen","plausibler Wochenblock")))
A28: 33 | B28: =SUMIFS(Datenbasis!$E$13:$E$211,Datenbasis!$H$13:$H$211,A28,Datenbasis!$A$13:$A$211,">="&Einstellungen!$B$4,Datenbasis!$A$13:$A$211,"<"&DATE(YEAR(Einstellungen!$B$4),MONTH(Einstellungen!$B$4)+1,1)) | C28: =SUMIFS(Datenbasis!$G$13:$G$211,Datenbasis!$H$13:$H$211,A28,Datenbasis!$A$13:$A$211,">="&Einstellungen!$B$4,Datenbasis!$A$13:$A$211,"<"&DATE(YEAR(Einstellungen!$B$4),MONTH(Einstellungen!$B$4)+1,1)) | D28: =IF(B28=0,"",IF(B28<2,"kleiner Block / Kontextaufbau",IF(B28>8,"hoher Wochenblock - Output sichtbar machen","plausibler Wochenblock")))

Sheet Monatstätigkeitsschein
A1: Monatstätigkeitsschein
A2: Druck-/kopierfähige Version. Die Formulierungen sind nutzenorientiert, aber auf die erfassten Tätigkeiten begrenzt.
A4: Monat | B4: =Einstellungen!F5 | C4: Auftraggeber | D4: =Einstellungen!B6 | E4: Auftragnehmer/in | F4: =Einstellungen!B7
A5: Gesamtstunden | B5: 35,65 | C5: Stundensatz | D5: 85 | E5: Betrag | F5: 3.030,25 €
A6: Kurzfazit | B6: Im Juni 2026 lagen die Schwerpunkte auf QR-Code-Tool-/Build-Analyse, technischer Arbeitsfähigkeit, erster Asana/Monday-Migrationssichtung sowie der konzeptionellen und technischen Vorbereitung der CMC-Studie 2027 einschließlich Testvarianten, POSTWURFSPEZIAL-Abstimmungen und KI-/InDesign-Automatisierung.
A11: Datum | B11: Bereich | C11: Tätigkeit | D11: Zeit | E11: Status
A12: 17.06.2026 | B12: QR Code | C12: Prozess-Refresh, Toolmarkt und Build-Option: Einarbeitung in den bestehenden QR-Code-Prozess, Ableitung der Soll-Anforderungen an ein neues Tool, erste Marktanalyse geeigneter Anbieter sowie technische Machbarkeitsprüfung eines eigenen Builds. Ergebnis: Grundlage für die QR-Tool-Gegenüberstellung: Soll-Kriterien, Markt-/Eigenbau-Perspektive und erste technische Stack-Klarheit wurden herausgearbeitet. | D12: 3,15 | E12: Abgeschlossen
A13: 18.06.2026 | B13: Technisches Setup | C13: Accounts, Mail und Arbeitsumgebung: Einrichtung und Prüfung der benötigten Accounts/Mail-Zugänge sowie kurze Orientierung in vorhandenen technischen Unterlagen und Arbeitsständen. Ergebnis: Reduziert Reibung im Folgeprozess und stellt sicher, dass weitere Analyse/Umsetzung ohne Zugriffshürden starten kann. | D13: 0,75 | E13: Abgeschlossen
A14: 18.06.2026 | B14: QR Code | C14: Technisches Setup und Stack-Vorauswahl: Verfeinerung des technischen Setups, Recherche möglicher Stack-Varianten und Eingrenzung der sinnvollsten Tool-/Build-Richtung. Ergebnis: Verdichtet die offenen Optionen technisch: Stack-Richtung, Toolanforderungen und Build-Risiken wurden so geklärt, dass die Gegenüberstellung belastbarer wird. | D14: 1,50 | E14: Abgeschlossen
A15: 18.06.2026 | B15: Asana / Monday | C15: Projektplan Migration Monday zu Asana: Aufsetzen eines ersten Projektplan-Rahmens für die Ablösung von Monday durch Asana inklusive erster Sichtung der Asana Features. | D15: 0,50 | E15: Initial
A16: 19.06.2026 | B16: Asana / Monday | C16: Board- und Prozessanalyse: Analyse vorhandener Monday-Boards und Prozesse mit Blick auf Migrationsrelevanz, Struktur, Dubletten und notwendige Übertragungslogik. Ergebnis: Identifiziert, was wirklich migriert werden muss und wo Prozessvereinfachung möglich ist, statt bestehende Komplexität ungeprüft nach Asana zu kopieren. | D16: 1,15 | E16: Initial
A17: 20.06.2026 | B17: QR Code | C17: Toolvergleich und Build-Abgleich: Detaillierte Analyse ausgewählter markttauglicher Tools und strukturierter Abgleich der Ergebnisse mit den Anforderungen an einen möglichen eigenen Build. Ergebnis: CMC_QR_Tool_Gegenueberstellung.xlsx mit Entscheidungsmatrix, Annahmen, Kurzfazit und nächsten Schritten; ergänzt durch Klarheit zum technischen Stack. | D17: 2,75 | E17: Abgeschlossen
A18: 21.06.2026 | B18: QR Code | C18: Gegenüberstellung prüfen, ergänzen und aufbereiten: Durchsicht der QR-Tool-Gegenüberstellung, Ergänzung offener Punkte und Aufbereitung der Inhalte für eine verständliche Entscheidungsgrundlage. Ergebnis: Die Gegenüberstellung ist für Robert klarer nutzbar: Bewertung, Annahmen, Risiken und nächste Schritte sind konsistenter herausgearbeitet. | D18: 0,50 | E18: Abgeschlossen
A19: 23.06.2026 | B19: QR Code | C19: Leistungsbeschreibung Short.io-Anfrage: Ausarbeitung einer strukturierten Leistungsbeschreibung für die geplante Short.io-Anfrage einschließlich fachlicher Anforderungen, relevanter Rahmenbedingungen und prüffähiger Anfrageinhalte als Grundlage für die weitere Anbieterabstimmung. | D19: 1,20
A20: 24.06.2026 | B20: Studie 2027 | C20: Abstimmung Testvarianten Studienkonzept: Abstimmung mit Jule, Simone und Cathleen zur Konzeption und Einordnung der vier vorgesehenen Testvarianten; Klärung zentraler Anforderungen, Variantenlogik und nächster Schritte für die weitere Studienplanung. | D20: 1,00
A21: 24.06.2026 | B21: Studie 2027 | C21: Einarbeitung Methodik und Studienunterlagen: Einarbeitung in das Studienthema, Recherche und fachliche Einordnung der verwendeten Methoden sowie Durcharbeitung der vorhandenen Präsentationsunterlagen zur Vorbereitung der weiteren konzeptionellen und inhaltlichen Ausarbeitung. | D21: 1,60
A22: 24.06.2026 | B22: Studie 2027 | C22: Briefing Präsentationsausarbeitung: Erstellung und Strukturierung eines Briefings für Cathleen zur weiteren Bearbeitung der Präsentation, inklusive Zusammenfassung relevanter Inhalte und Anforderungen für die nächste Ausarbeitungsschleife. | D22: 0,50
A23: 25.06.2026 | B23: Studie 2027 | C23: Finalisierung Briefing und Visualisierungstexte: Finalisierung des Briefings für Cathleen sowie Ausarbeitung und Präzisierung von Textvorschlägen und Visualisierungsansätzen für die Studienpräsentation. | D23: 1,20
A24: 25.06.2026 | B24: Studie 2027 | C24: Anfrage POSTWURFSPEZIAL: Vorbereitung und Formulierung der Anfrage zu POSTWURFSPEZIAL unter Berücksichtigung der für die Studienumsetzung relevanten Anforderungen und Abstimmungsbedarfe. | D24: 0,60
A25: 25.06.2026 | B25: Studie 2027 | C25: Ist-/Soll-Analyse Studienmailing: Durchführung einer Ist-/Soll-Analyse für die Erstellung des Studienmailings; Prüfung des Partnerfragebogens und der InDesign-Vorlagen sowie Bewertung möglicher Automatisierungsansätze einschließlich teambezogener Abstimmungen zu Umsetzbarkeit und Vorgehen. | D25: 2,15
A26: 25.06.2026 | B26: Studie 2027 | C26: Klärung Pre-Test-Vorgehen: Klärung des geplanten Pre-Test-Vorgehens mit dem Team, einschließlich Abstimmung offener Punkte und Einordnung der nächsten Schritte für die weitere Studienvorbereitung. | D26: 0,30
A27: 25.06.2026 | B27: Studie 2027 | C27: Statusabfrage und Arbeitspaket-Update: Einholung aktueller Statusinformationen und Aktualisierung der Arbeitspakete bis zum 03.07.; Strukturierung der offenen Punkte und Nachverfolgung relevanter Zuständigkeiten. | D27: 0,50
A28: 26.06.2026 | B28: Studie 2027 | C28: Testskript und Zusammenfassung: Erstellung eines Skripts und Zusammenfassung der Inhalte als Testfassung für Jule und Simone, einschließlich Aufbereitung der relevanten Punkte für Prüfung, Feedback und weitere Abstimmung. | D28: 1,55
A29: 26.06.2026 | B29: Studie 2027 | C29: Vor-/Nachbereitung Christina-Abstimmung: Vor- und Nachbereitung der Abstimmung mit Christina einschließlich Terminabgleich, Strukturierung relevanter Inhalte und Ableitung der nächsten Schritte für die weitere Studien- und Präsentationsarbeit. | D29: 1,10
A30: 26.06.2026 | B30: Studie 2027 | C30: Pre-Test-Abstimmung Lone/Lisa: Abstimmung mit Lone und Lisa zum Pre-Test sowie zum Stand der bis Freitag vorgesehenen To-dos; Klärung offener Punkte, Zuständigkeiten und nächster Schritte. | D30: 0,70
... A41: 30.06.2026 | B41: Studie 2027 | C41: Review und Weitergabe Präsentation: Review der von Cathleen überarbeiteten Präsentation; Prüfung der inhaltlichen Anpassungen und Weitergabe relevanter Rückmeldungen für die weitere Bearbeitung. | D41: 0,60
A44: Bestätigung
A45: Die oben aufgeführten Leistungen wurden wahrheitsgemäß dokumentiert und beziehen sich auf den Arbeitsstand des ausgewählten Monats.
A46: Ort/Datum: ______________________________ Unterschrift: ______________________________
