Workbook

Sheet Zeiterfassung
A1: Datum | B1: Aufgabe | C1: Arbeitszeit (Stunden)
A2: KW 28 (06.07.–12.07.2026) | C2: 21,55 Std.
A3: 6. Juli 2026 | B3: Studie 2027: Debrief mit Simone und Jule zum bisherigen Teststand; Sammlung offener Punkte und Einordnung der nächsten Arbeitsschritte. | C3: 1
A4: 6. Juli 2026 | B4: Studie 2027: Erstellung eines neuen Testpakets auf Basis des Debriefings sowie Weiterentwicklung des JSON-Builder-Tools für Jule und Simone, inklusive Prüfchecks und E-Mail-Output. | C4: 3.4
A5: 7. Juli 2026 | B5: Studie 2027: Kommunikation der nächsten Schritte an Jule und Simone, Auswertung der Testlaufzeiten sowie Aufbereitung eines Status-Updates zur Studie 2027. | C5: 1.45
A6: 7. Juli 2026 | B6: Studie 2027: Weiterentwicklung des JSON-Builder-Tools einschließlich Fehlerbehebung, zusätzlicher Prüfungen und optischer Optimierung; weitere Skriptoptimierung und Vorbereitung einer neuen Testrunde. | C6: 2.75
A7: 8. Juli 2026 | B7: Studie 2027: Auswertung des JSON-Builder- und Bildertests, Einarbeitung weiterer Anmerkungen sowie Zusammenstellung eines Testpakets für Simone. | C7: 1.1
A8: 8. Juli 2026 | B8: Studie 2027: Abstimmung mit Robert sowie Zusammenfassung relevanter Punkte und nächster Schritte. | C8: 1.2
A9: 8. Juli 2026 | B9: Studie 2027: Debrief mit Simone zum letzten Testlauf, Klärung offener Fragen und Ableitung weiterer Anpassungsbedarfe. | C9: 0.7
A10: 8. Juli 2026 | B10: Studie 2027: Einarbeitung in die Sales-Präsentation und Beginn der Erstellung eines Briefings für die weitere Ausarbeitung. | C10: 1.5
A11: 8. Juli 2026 | B11: Studie 2027: Überarbeitung des JSON-Builders anhand von Simones Feedback sowie Vorbereitung einer erneuten Testrunde. | C11: 1.25
A12: 9. Juli 2026 | B12: Studie 2027: Fertigstellung des Sales-Präsentationsbriefings unter Einbindung des Inputs von Maria und Lisa. | C12: 0.75
A13: 9. Juli 2026 | B13: Studie 2027: Abstimmung mit Simone zur Durchführung des Ende-zu-Ende-Tests sowie Debrief zum letzten Testlauf. | C13: 0.45
A14: 9. Juli 2026 | B14: Studie 2027: Überarbeitung des JSON-Builders anhand von Simones Feedback, Vorbereitung einer erneuten Testrunde und Aufbau eines KI-Text-Builders. | C14: 2.25
... A18: 10. Juli 2026 | B18: Überstunden | C18: -1.55
B19: Summe Stunden KW 28 | C19: =SUM(C3:C18) -> 20
A20: Hinweis: Stunden oberhalb des KW-Budgets von 20,00 Std. sind als Überstunden ausgewiesen und nicht abrechenbar.

Sheet Budgetübersicht
A1: Budgetübersicht Zeit
A3: Budget-Eingaben
A4: Monatsbudget (Std.) | B4: =IF(Einstellungen!B14="","",Einstellungen!B14)
A5: KW-Budget (Std.) | B5: =IF(Einstellungen!B15="","",Einstellungen!B15) -> 20
A7: Monat | B7: Gebucht (Std.) | C7: Abrechenbar (Std.) | D7: Überstunden (Std.) | E7: Budget (Std.) | F7: Offen (Std.) | G7: Stundensatz (EUR) | H7: Abrechenbar (EUR)
A8: =DATE(2026,1,1) -> 46023 | B8: =SUMIFS(Datenbasis!$E$13:$E$214,Datenbasis!$A$13:$A$214,">="&A8,Datenbasis!$A$13:$A$214,"<"&EDATE(A8,1)) -> 0 | C8: =SUMIFS(Datenbasis!$L$13:$L$214,Datenbasis!$A$13:$A$214,">="&A8,Datenbasis!$A$13:$A$214,"<"&EDATE(A8,1)) -> 0 | D8: =SUMIFS(Datenbasis!$M$13:$M$214,Datenbasis!$A$13:$A$214,">="&A8,Datenbasis!$A$13:$A$214,"<"&EDATE(A8,1)) -> 0 | E8: =IF(Einstellungen!$B$14="","",Einstellungen!$B$14) | F8: =IF(E8="","",MAX(0,E8-B8)) | G8: =IF(C8="","",Einstellungen!$B$5) -> 85 | H8: =IF(C8="","",C8*G8) -> 0
A9: =DATE(2026,2,1) -> 46054 | B9: =SUMIFS(Datenbasis!$E$13:$E$214,Datenbasis!$A$13:$A$214,">="&A9,Datenbasis!$A$13:$A$214,"<"&EDATE(A9,1)) -> 0 | C9: =SUMIFS(Datenbasis!$L$13:$L$214,Datenbasis!$A$13:$A$214,">="&A9,Datenbasis!$A$13:$A$214,"<"&EDATE(A9,1)) -> 0 | D9: =SUMIFS(Datenbasis!$M$13:$M$214,Datenbasis!$A$13:$A$214,">="&A9,Datenbasis!$A$13:$A$214,"<"&EDATE(A9,1)) -> 0 | E9: =IF(Einstellungen!$B$14="","",Einstellungen!$B$14) | F9: =IF(E9="","",MAX(0,E9-B9)) | G9: =IF(C9="","",Einstellungen!$B$5) -> 85 | H9: =IF(C9="","",C9*G9) -> 0
A10: =DATE(2026,3,1) -> 46082 | B10: =SUMIFS(Datenbasis!$E$13:$E$214,Datenbasis!$A$13:$A$214,">="&A10,Datenbasis!$A$13:$A$214,"<"&EDATE(A10,1)) -> 0 | C10: =SUMIFS(Datenbasis!$L$13:$L$214,Datenbasis!$A$13:$A$214,">="&A10,Datenbasis!$A$13:$A$214,"<"&EDATE(A10,1)) -> 0 | D10: =SUMIFS(Datenbasis!$M$13:$M$214,Datenbasis!$A$13:$A$214,">="&A10,Datenbasis!$A$13:$A$214,"<"&EDATE(A10,1)) -> 0 | E10: =IF(Einstellungen!$B$14="","",Einstellungen!$B$14) | F10: =IF(E10="","",MAX(0,E10-B10)) | G10: =IF(C10="","",Einstellungen!$B$5) -> 85 | H10: =IF(C10="","",C10*G10) -> 0
A11: =DATE(2026,4,1) -> 46113 | B11: =SUMIFS(Datenbasis!$E$13:$E$214,Datenbasis!$A$13:$A$214,">="&A11,Datenbasis!$A$13:$A$214,"<"&EDATE(A11,1)) -> 0 | C11: =SUMIFS(Datenbasis!$L$13:$L$214,Datenbasis!$A$13:$A$214,">="&A11,Datenbasis!$A$13:$A$214,"<"&EDATE(A11,1)) -> 0 | D11: =SUMIFS(Datenbasis!$M$13:$M$214,Datenbasis!$A$13:$A$214,">="&A11,Datenbasis!$A$13:$A$214,"<"&EDATE(A11,1)) -> 0 | E11: =IF(Einstellungen!$B$14="","",Einstellungen!$B$14) | F11: =IF(E11="","",MAX(0,E11-B11)) | G11: =IF(C11="","",Einstellungen!$B$5) -> 85 | H11: =IF(C11="","",C11*G11) -> 0
A12: =DATE(2026,5,1) -> 46143 | B12: =SUMIFS(Datenbasis!$E$13:$E$214,Datenbasis!$A$13:$A$214,">="&A12,Datenbasis!$A$13:$A$214,"<"&EDATE(A12,1)) -> 0 | C12: =SUMIFS(Datenbasis!$L$13:$L$214,Datenbasis!$A$13:$A$214,">="&A12,Datenbasis!$A$13:$A$214,"<"&EDATE(A12,1)) -> 0 | D12: =SUMIFS(Datenbasis!$M$13:$M$214,Datenbasis!$A$13:$A$214,">="&A12,Datenbasis!$A$13:$A$214,"<"&EDATE(A12,1)) -> 0 | E12: =IF(Einstellungen!$B$14="","",Einstellungen!$B$14) | F12: =IF(E12="","",MAX(0,E12-B12)) | G12: =IF(C12="","",Einstellungen!$B$5) -> 85 | H12: =IF(C12="","",C12*G12) -> 0
A13: =DATE(2026,6,1) -> 46174 | B13: =SUMIFS(Datenbasis!$E$13:$E$214,Datenbasis!$A$13:$A$214,">="&A13,Datenbasis!$A$13:$A$214,"<"&EDATE(A13,1)) -> 35.65 | C13: =SUMIFS(Datenbasis!$L$13:$L$214,Datenbasis!$A$13:$A$214,">="&A13,Datenbasis!$A$13:$A$214,"<"&EDATE(A13,1)) -> 35.65 | D13: =SUMIFS(Datenbasis!$M$13:$M$214,Datenbasis!$A$13:$A$214,">="&A13,Datenbasis!$A$13:$A$214,"<"&EDATE(A13,1)) -> 0 | E13: =IF(Einstellungen!$B$14="","",Einstellungen!$B$14) | F13: =IF(E13="","",MAX(0,E13-B13)) | G13: =IF(C13="","",Einstellungen!$B$5) -> 85 | H13: =IF(C13="","",C13*G13) -> 3030.25
A14: =DATE(2026,7,1) -> 46204 | B14: =SUMIFS(Datenbasis!$E$13:$E$214,Datenbasis!$A$13:$A$214,">="&A14,Datenbasis!$A$13:$A$214,"<"&EDATE(A14,1)) -> 61.55 | C14: =SUMIFS(Datenbasis!$L$13:$L$214,Datenbasis!$A$13:$A$214,">="&A14,Datenbasis!$A$13:$A$214,"<"&EDATE(A14,1)) -> 57 | D14: =SUMIFS(Datenbasis!$M$13:$M$214,Datenbasis!$A$13:$A$214,">="&A14,Datenbasis!$A$13:$A$214,"<"&EDATE(A14,1)) -> 4.55 | E14: =IF(Einstellungen!$B$14="","",Einstellungen!$B$14) | F14: =IF(E14="","",MAX(0,E14-B14)) | G14: =IF(C14="","",Einstellungen!$B$5) -> 85 | H14: =IF(C14="","",C14*G14) -> 4845
A15: =DATE(2026,8,1) -> 46235 | B15: =SUMIFS(Datenbasis!$E$13:$E$214,Datenbasis!$A$13:$A$214,">="&A15,Datenbasis!$A$13:$A$214,"<"&EDATE(A15,1)) -> 0 | C15: =SUMIFS(Datenbasis!$L$13:$L$214,Datenbasis!$A$13:$A$214,">="&A15,Datenbasis!$A$13:$A$214,"<"&EDATE(A15,1)) -> 0 | D15: =SUMIFS(Datenbasis!$M$13:$M$214,Datenbasis!$A$13:$A$214,">="&A15,Datenbasis!$A$13:$A$214,"<"&EDATE(A15,1)) -> 0 | E15: =IF(Einstellungen!$B$14="","",Einstellungen!$B$14) | F15: =IF(E15="","",MAX(0,E15-B15)) | G15: =IF(C15="","",Einstellungen!$B$5) -> 85 | H15: =IF(C15="","",C15*G15) -> 0
A16: =DATE(2026,9,1) -> 46266 | B16: =SUMIFS(Datenbasis!$E$13:$E$214,Datenbasis!$A$13:$A$214,">="&A16,Datenbasis!$A$13:$A$214,"<"&EDATE(A16,1)) -> 0 | C16: =SUMIFS(Datenbasis!$L$13:$L$214,Datenbasis!$A$13:$A$214,">="&A16,Datenbasis!$A$13:$A$214,"<"&EDATE(A16,1)) -> 0 | D16: =SUMIFS(Datenbasis!$M$13:$M$214,Datenbasis!$A$13:$A$214,">="&A16,Datenbasis!$A$13:$A$214,"<"&EDATE(A16,1)) -> 0 | E16: =IF(Einstellungen!$B$14="","",Einstellungen!$B$14) | F16: =IF(E16="","",MAX(0,E16-B16)) | G16: =IF(C16="","",Einstellungen!$B$5) -> 85 | H16: =IF(C16="","",C16*G16) -> 0
A17: =DATE(2026,10,1) -> 46296 | B17: =SUMIFS(Datenbasis!$E$13:$E$214,Datenbasis!$A$13:$A$214,">="&A17,Datenbasis!$A$13:$A$214,"<"&EDATE(A17,1)) -> 0 | C17: =SUMIFS(Datenbasis!$L$13:$L$214,Datenbasis!$A$13:$A$214,">="&A17,Datenbasis!$A$13:$A$214,"<"&EDATE(A17,1)) -> 0 | D17: =SUMIFS(Datenbasis!$M$13:$M$214,Datenbasis!$A$13:$A$214,">="&A17,Datenbasis!$A$13:$A$214,"<"&EDATE(A17,1)) -> 0 | E17: =IF(Einstellungen!$B$14="","",Einstellungen!$B$14) | F17: =IF(E17="","",MAX(0,E17-B17)) | G17: =IF(C17="","",Einstellungen!$B$5) -> 85 | H17: =IF(C17="","",C17*G17) -> 0
A18: =DATE(2026,11,1) -> 46327 | B18: =SUMIFS(Datenbasis!$E$13:$E$214,Datenbasis!$A$13:$A$214,">="&A18,Datenbasis!$A$13:$A$214,"<"&EDATE(A18,1)) -> 0 | C18: =SUMIFS(Datenbasis!$L$13:$L$214,Datenbasis!$A$13:$A$214,">="&A18,Datenbasis!$A$13:$A$214,"<"&EDATE(A18,1)) -> 0 | D18: =SUMIFS(Datenbasis!$M$13:$M$214,Datenbasis!$A$13:$A$214,">="&A18,Datenbasis!$A$13:$A$214,"<"&EDATE(A18,1)) -> 0 | E18: =IF(Einstellungen!$B$14="","",Einstellungen!$B$14) | F18: =IF(E18="","",MAX(0,E18-B18)) | G18: =IF(C18="","",Einstellungen!$B$5) -> 85 | H18: =IF(C18="","",C18*G18) -> 0
A19: =DATE(2026,12,1) -> 46357 | B19: =SUMIFS(Datenbasis!$E$13:$E$214,Datenbasis!$A$13:$A$214,">="&A19,Datenbasis!$A$13:$A$214,"<"&EDATE(A19,1)) -> 0 | C19: =SUMIFS(Datenbasis!$L$13:$L$214,Datenbasis!$A$13:$A$214,">="&A19,Datenbasis!$A$13:$A$214,"<"&EDATE(A19,1)) -> 0 | D19: =SUMIFS(Datenbasis!$M$13:$M$214,Datenbasis!$A$13:$A$214,">="&A19,Datenbasis!$A$13:$A$214,"<"&EDATE(A19,1)) -> 0 | E19: =IF(Einstellungen!$B$14="","",Einstellungen!$B$14) | F19: =IF(E19="","",MAX(0,E19-B19)) | G19: =IF(C19="","",Einstellungen!$B$5) -> 85 | H19: =IF(C19="","",C19*G19) -> 0
A22: KW | B22: Gebucht (Std.) | C22: Abrechenbar (Std.) | D22: Überstunden (Std.) | E22: Budget (Std.) | F22: Offen (Std.) | G22: Stundensatz (EUR) | H22: Abrechenbar (EUR)
A23: 1 | B23: =IF(SUMIFS(Datenbasis!$E$13:$E$214,Datenbasis!$H$13:$H$214,A23)=0,"",SUMIFS(Datenbasis!$E$13:$E$214,Datenbasis!$H$13:$H$214,A23)) | C23: =IF(B23="","",SUMIFS(Datenbasis!$L$13:$L$214,Datenbasis!$H$13:$H$214,A23)) | D23: =IF(B23="","",SUMIFS(Datenbasis!$M$13:$M$214,Datenbasis!$H$13:$H$214,A23)) | E23: =IF(OR(B23="",Einstellungen!$B$15=""),"",Einstellungen!$B$15) | F23: =IF(E23="","",MAX(0,E23-B23)) | G23: =IF(C23="","",Einstellungen!$B$5) | H23: =IF(C23="","",C23*G23)
A24: 2 | B24: =IF(SUMIFS(Datenbasis!$E$13:$E$214,Datenbasis!$H$13:$H$214,A24)=0,"",SUMIFS(Datenbasis!$E$13:$E$214,Datenbasis!$H$13:$H$214,A24)) | C24: =IF(B24="","",SUMIFS(Datenbasis!$L$13:$L$214,Datenbasis!$H$13:$H$214,A24)) | D24: =IF(B24="","",SUMIFS(Datenbasis!$M$13:$M$214,Datenbasis!$H$13:$H$214,A24)) | E24: =IF(OR(B24="",Einstellungen!$B$15=""),"",Einstellungen!$B$15) | F24: =IF(E24="","",MAX(0,E24-B24)) | G24: =IF(C24="","",Einstellungen!$B$5) | H24: =IF(C24="","",C24*G24)
A25: 3 | B25: =IF(SUMIFS(Datenbasis!$E$13:$E$214,Datenbasis!$H$13:$H$214,A25)=0,"",SUMIFS(Datenbasis!$E$13:$E$214,Datenbasis!$H$13:$H$214,A25)) | C25: =IF(B25="","",SUMIFS(Datenbasis!$L$13:$L$214,Datenbasis!$H$13:$H$214,A25)) | D25: =IF(B25="","",SUMIFS(Datenbasis!$M$13:$M$214,Datenbasis!$H$13:$H$214,A25)) | E25: =IF(OR(B25="",Einstellungen!$B$15=""),"",Einstellungen!$B$15) | F25: =IF(E25="","",MAX(0,E25-B25)) | G25: =IF(C25="","",Einstellungen!$B$5) | H25: =IF(C25="","",C25*G25)
A26: 4 | B26: =IF(SUMIFS(Datenbasis!$E$13:$E$214,Datenbasis!$H$13:$H$214,A26)=0,"",SUMIFS(Datenbasis!$E$13:$E$214,Datenbasis!$H$13:$H$214,A26)) | C26: =IF(B26="","",SUMIFS(Datenbasis!$L$13:$L$214,Datenbasis!$H$13:$H$214,A26)) | D26: =IF(B26="","",SUMIFS(Datenbasis!$M$13:$M$214,Datenbasis!$H$13:$H$214,A26)) | E26: =IF(OR(B26="",Einstellungen!$B$15=""),"",Einstellungen!$B$15) | F26: =IF(E26="","",MAX(0,E26-B26)) | G26: =IF(C26="","",Einstellungen!$B$5) | H26: =IF(C26="","",C26*G26)
A27: 5 | B27: =IF(SUMIFS(Datenbasis!$E$13:$E$214,Datenbasis!$H$13:$H$214,A27)=0,"",SUMIFS(Datenbasis!$E$13:$E$214,Datenbasis!$H$13:$H$214,A27)) | C27: =IF(B27="","",SUMIFS(Datenbasis!$L$13:$L$214,Datenbasis!$H$13:$H$214,A27)) | D27: =IF(B27="","",SUMIFS(Datenbasis!$M$13:$M$214,Datenbasis!$H$13:$H$214,A27)) | E27: =IF(OR(B27="",Einstellungen!$B$15=""),"",Einstellungen!$B$15) | F27: =IF(E27="","",MAX(0,E27-B27)) | G27: =IF(C27="","",Einstellungen!$B$5) | H27: =IF(C27="","",C27*G27)
A28: 6 | B28: =IF(SUMIFS(Datenbasis!$E$13:$E$214,Datenbasis!$H$13:$H$214,A28)=0,"",SUMIFS(Datenbasis!$E$13:$E$214,Datenbasis!$H$13:$H$214,A28)) | C28: =IF(B28="","",SUMIFS(Datenbasis!$L$13:$L$214,Datenbasis!$H$13:$H$214,A28)) | D28: =IF(B28="","",SUMIFS(Datenbasis!$M$13:$M$214,Datenbasis!$H$13:$H$214,A28)) | E28: =IF(OR(B28="",Einstellungen!$B$15=""),"",Einstellungen!$B$15) | F28: =IF(E28="","",MAX(0,E28-B28)) | G28: =IF(C28="","",Einstellungen!$B$5) | H28: =IF(C28="","",C28*G28)
A29: 7 | B29: =IF(SUMIFS(Datenbasis!$E$13:$E$214,Datenbasis!$H$13:$H$214,A29)=0,"",SUMIFS(Datenbasis!$E$13:$E$214,Datenbasis!$H$13:$H$214,A29)) | C29: =IF(B29="","",SUMIFS(Datenbasis!$L$13:$L$214,Datenbasis!$H$13:$H$214,A29)) | D29: =IF(B29="","",SUMIFS(Datenbasis!$M$13:$M$214,Datenbasis!$H$13:$H$214,A29)) | E29: =IF(OR(B29="",Einstellungen!$B$15=""),"",Einstellungen!$B$15) | F29: =IF(E29="","",MAX(0,E29-B29)) | G29: =IF(C29="","",Einstellungen!$B$5) | H29: =IF(C29="","",C29*G29)
A30: 8 | B30: =IF(SUMIFS(Datenbasis!$E$13:$E$214,Datenbasis!$H$13:$H$214,A30)=0,"",SUMIFS(Datenbasis!$E$13:$E$214,Datenbasis!$H$13:$H$214,A30)) | C30: =IF(B30="","",SUMIFS(Datenbasis!$L$13:$L$214,Datenbasis!$H$13:$H$214,A30)) | D30: =IF(B30="","",SUMIFS(Datenbasis!$M$13:$M$214,Datenbasis!$H$13:$H$214,A30)) | E30: =IF(OR(B30="",Einstellungen!$B$15=""),"",Einstellungen!$B$15) | F30: =IF(E30="","",MAX(0,E30-B30)) | G30: =IF(C30="","",Einstellungen!$B$5) | H30: =IF(C30="","",C30*G30)
A31: 9 | B31: =IF(SUMIFS(Datenbasis!$E$13:$E$214,Datenbasis!$H$13:$H$214,A31)=0,"",SUMIFS(Datenbasis!$E$13:$E$214,Datenbasis!$H$13:$H$214,A31)) | C31: =IF(B31="","",SUMIFS(Datenbasis!$L$13:$L$214,Datenbasis!$H$13:$H$214,A31)) | D31: =IF(B31="","",SUMIFS(Datenbasis!$M$13:$M$214,Datenbasis!$H$13:$H$214,A31)) | E31: =IF(OR(B31="",Einstellungen!$B$15=""),"",Einstellungen!$B$15) | F31: =IF(E31="","",MAX(0,E31-B31)) | G31: =IF(C31="","",Einstellungen!$B$5) | H31: =IF(C31="","",C31*G31)
A32: 10 | B32: =IF(SUMIFS(Datenbasis!$E$13:$E$214,Datenbasis!$H$13:$H$214,A32)=0,"",SUMIFS(Datenbasis!$E$13:$E$214,Datenbasis!$H$13:$H$214,A32)) | C32: =IF(B32="","",SUMIFS(Datenbasis!$L$13:$L$214,Datenbasis!$H$13:$H$214,A32)) | D32: =IF(B32="","",SUMIFS(Datenbasis!$M$13:$M$214,Datenbasis!$H$13:$H$214,A32)) | E32: =IF(OR(B32="",Einstellungen!$B$15=""),"",Einstellungen!$B$15) | F32: =IF(E32="","",MAX(0,E32-B32)) | G32: =IF(C32="","",Einstellungen!$B$5) | H32: =IF(C32="","",C32*G32)
A33: 11 | B33: =IF(SUMIFS(Datenbasis!$E$13:$E$214,Datenbasis!$H$13:$H$214,A33)=0,"",SUMIFS(Datenbasis!$E$13:$E$214,Datenbasis!$H$13:$H$214,A33)) | C33: =IF(B33="","",SUMIFS(Datenbasis!$L$13:$L$214,Datenbasis!$H$13:$H$214,A33)) | D33: =IF(B33="","",SUMIFS(Datenbasis!$M$13:$M$214,Datenbasis!$H$13:$H$214,A33)) | E33: =IF(OR(B33="",Einstellungen!$B$15=""),"",Einstellungen!$B$15) | F33: =IF(E33="","",MAX(0,E33-B33)) | G33: =IF(C33="","",Einstellungen!$B$5) | H33: =IF(C33="","",C33*G33)
A34: 12 | B34: =IF(SUMIFS(Datenbasis!$E$13:$E$214,Datenbasis!$H$13:$H$214,A34)=0,"",SUMIFS(Datenbasis!$E$13:$E$214,Datenbasis!$H$13:$H$214,A34)) | C34: =IF(B34="","",SUMIFS(Datenbasis!$L$13:$L$214,Datenbasis!$H$13:$H$214,A34)) | D34: =IF(B34="","",SUMIFS(Datenbasis!$M$13:$M$214,Datenbasis!$H$13:$H$214,A34)) | E34: =IF(OR(B34="",Einstellungen!$B$15=""),"",Einstellungen!$B$15) | F34: =IF(E34="","",MAX(0,E34-B34)) | G34: =IF(C34="","",Einstellungen!$B$5) | H34: =IF(C34="","",C34*G34)
... A75: 53 | B75: =IF(SUMIFS(Datenbasis!$E$13:$E$214,Datenbasis!$H$13:$H$214,A75)=0,"",SUMIFS(Datenbasis!$E$13:$E$214,Datenbasis!$H$13:$H$214,A75)) | C75: =IF(B75="","",SUMIFS(Datenbasis!$L$13:$L$214,Datenbasis!$H$13:$H$214,A75)) | D75: =IF(B75="","",SUMIFS(Datenbasis!$M$13:$M$214,Datenbasis!$H$13:$H$214,A75)) | E75: =IF(OR(B75="",Einstellungen!$B$15=""),"",Einstellungen!$B$15) | F75: =IF(E75="","",MAX(0,E75-B75)) | G75: =IF(C75="","",Einstellungen!$B$5) | H75: =IF(C75="","",C75*G75)

Sheet Einstellungen
A1: Einstellungen
A2: Monat und Stundensatz hier ändern; alle Auswertungen und der Tätigkeitsschein greifen darauf zurück.
A4: Monat beginnt am | B4: 46174 | D4: Kategorie-Liste | E4: Status-Liste | F4: Monatslabel
A5: Stundensatz | B5: 85 | D5: Analyse / Recherche | E5: Initial | F5: =CHOOSE(MONTH(B4),"Januar","Februar","März","April","Mai","Juni","Juli","August","September","Oktober","November","Dezember")&" "&YEAR(B4) -> Juni 2026
A6: Auftraggeber | B6: Robert | D6: Technische Konzeption | E6: In Arbeit
A7: Auftragnehmer/in | B7: Maria | D7: Projektplanung | E7: Abgeschlossen
A8: Währung | B8: EUR | D8: Setup / Administration
A9: Max. Tracking-Zeilen | B9: 200 | D9: Umsetzung / Dokumentation
A10: Hinweis | B10: Zeiterfassung ist als Screenshot-Ansicht für Robert formatiert. Details/Kategorien liegen in der Datenbasis.
A11: Datei-Zweck | B11: Laufendes Time Tracking + monatlicher Tätigkeitsschein
A13: Budget-Eingaben
A14: Monatsbudget (Std.)
A15: KW-Budget (Std.) | B15: 20
A16: Hinweis | B16: Gelbe Zellen ausfüllen; Restbudget berechnet sich automatisch.

Sheet Datenbasis
A1: Datenbasis
A2: Interne Arbeitsdaten für Auswertung und Tätigkeitsschein. Roberts Screenshot wird aus dem Blatt Zeiterfassung erstellt.
A4: Monat | B4: Stundensatz | D4: Monatsstunden | E4: Monatsbetrag | G4: Aktuelle KW | H4: KW-Start | I4: Gebucht (Std.) | J4: Budget (Std.) | K4: Offen/Überstunden (Std.)
A5: =Einstellungen!F5 -> Juni 2026 | B5: =Einstellungen!B5 -> 85 | D5: =SUMIFS(E13:E214,A13:A214,">="&Einstellungen!B4,A13:A214,"<"&DATE(YEAR(Einstellungen!B4),MONTH(Einstellungen!B4)+1,1)) -> 35.65 | E5: =SUMIFS(G13:G214,A13:A214,">="&Einstellungen!B4,A13:A214,"<"&DATE(YEAR(Einstellungen!B4),MONTH(Einstellungen!B4)+1,1)) -> 3030.25 | G5: =WEEKNUM(TODAY(),21) -> 29 | H5: =TODAY()-WEEKDAY(TODAY(),2)+1 -> 46216 | I5: =SUMIFS($E$13:$E$214,$A$13:$A$214,">="&$H$5,$A$13:$A$214,"<"&$H$5+7) -> 23 | J5: =Einstellungen!$B$15 -> 20 | K5: =IF(OR(I5="",J5=""),"",J5-I5) -> -3
G6: Anzeige aktualisiert sich beim Öffnen/Neuberechnen der Datei; KW-Budget steht in Einstellungen!B15. Negative Werte in K5 sind Überstunden.
A12: Datum | B12: Bereich | C12: Aufgabe kurz | D12: Tätigkeit | E12: Zeit (Std.) | F12: Stundensatz | G12: Betrag | H12: KW | I12: Monat | J12: Kategorie | K12: Status | L12: Abrechenbar (Std.) | M12: Überstunden (Std.) | N12: KW-Gesamt (Std.) | O12: KW-Offen/Über (Std.)
A13: 46190 | B13: QR Code | C13: Prozess-Refresh, Toolmarkt und Build-Option | D13: Einarbeitung in den bestehenden QR-Code-Prozess, Ableitung der Soll-Anforderungen an ein neues Tool, erste Marktanalyse geeigneter Anbieter sowie technische Machbarkeitsprüfung eines eigenen Builds. Ergebnis: Grundlage für die QR-Tool-Gegenüberstellung: Soll-Kriterien, Markt-/Eigenbau-Perspektive und erste technische Stack-Klarheit wurden herausgearbeitet. | E13: 3.15 | F13: =IF(A13="","",Einstellungen!$B$5) -> 85 | G13: =IF(A13="","",L13*F13) -> 267.75 | H13: =IF(A13="","",WEEKNUM(A13,21)) -> 25 | I13: =IF(A13="","",TEXT(A13,"[$-de-DE]MMMM YYYY")) -> Juni YYYY | J13: Analyse / Recherche | K13: Abgeschlossen | L13: =IF(A13="","",IF(Einstellungen!$B$15="","",MAX(0,MIN(E13,Einstellungen!$B$15-(SUMIFS($E$13:$E13,$H$13:$H13,H13)-E13))))) -> 3.15 | M13: =IF(A13="","",IF(L13="","",E13-L13)) -> 0 | N13: =IF(A13="","",SUMIFS($E$13:$E$214,$H$13:$H$214,H13)) -> 10.3 | O13: =IF(A13="","",IF(Einstellungen!$B$15="","",Einstellungen!$B$15-N13)) -> 9.7
A14: 46191 | B14: Technisches Setup | C14: Accounts, Mail und Arbeitsumgebung | D14: Einrichtung und Prüfung der benötigten Accounts/Mail-Zugänge sowie kurze Orientierung in vorhandenen technischen Unterlagen und Arbeitsständen. Ergebnis: Reduziert Reibung im Folgeprozess und stellt sicher, dass weitere Analyse/Umsetzung ohne Zugriffshürden starten kann. | E14: 0.75 | F14: =IF(A14="","",Einstellungen!$B$5) -> 85 | G14: =IF(A14="","",L14*F14) -> 63.75 | H14: =IF(A14="","",WEEKNUM(A14,21)) -> 25 | I14: =IF(A14="","",TEXT(A14,"[$-de-DE]MMMM YYYY")) -> Juni YYYY | J14: Setup / Administration | K14: Abgeschlossen | L14: =IF(A14="","",IF(Einstellungen!$B$15="","",MAX(0,MIN(E14,Einstellungen!$B$15-(SUMIFS($E$13:$E14,$H$13:$H14,H14)-E14))))) -> 0.75 | M14: =IF(A14="","",IF(L14="","",E14-L14)) -> 0 | N14: =IF(A14="","",SUMIFS($E$13:$E$214,$H$13:$H$214,H14)) -> 10.3 | O14: =IF(A14="","",IF(Einstellungen!$B$15="","",Einstellungen!$B$15-N14)) -> 9.7
A15: 46191 | B15: QR Code | C15: Technisches Setup und Stack-Vorauswahl | D15: Verfeinerung des technischen Setups, Recherche möglicher Stack-Varianten und Eingrenzung der sinnvollsten Tool-/Build-Richtung. Ergebnis: Verdichtet die offenen Optionen technisch: Stack-Richtung, Toolanforderungen und Build-Risiken wurden so geklärt, dass die Gegenüberstellung belastbarer wird. | E15: 1.5 | F15: =IF(A15="","",Einstellungen!$B$5) -> 85 | G15: =IF(A15="","",L15*F15) -> 127.5 | H15: =IF(A15="","",WEEKNUM(A15,21)) -> 25 | I15: =IF(A15="","",TEXT(A15,"[$-de-DE]MMMM YYYY")) -> Juni YYYY | J15: Technische Konzeption | K15: Abgeschlossen | L15: =IF(A15="","",IF(Einstellungen!$B$15="","",MAX(0,MIN(E15,Einstellungen!$B$15-(SUMIFS($E$13:$E15,$H$13:$H15,H15)-E15))))) -> 1.5 | M15: =IF(A15="","",IF(L15="","",E15-L15)) -> 0 | N15: =IF(A15="","",SUMIFS($E$13:$E$214,$H$13:$H$214,H15)) -> 10.3 | O15: =IF(A15="","",IF(Einstellungen!$B$15="","",Einstellungen!$B$15-N15)) -> 9.7
A16: 46191 | B16: Asana / Monday | C16: Projektplan Migration Monday zu Asana | D16: Aufsetzen eines ersten Projektplan-Rahmens für die Ablösung von Monday durch Asana inklusive erster Sichtung der Asana Features. | E16: 0.5 | F16: =IF(A16="","",Einstellungen!$B$5) -> 85 | G16: =IF(A16="","",L16*F16) -> 42.5 | H16: =IF(A16="","",WEEKNUM(A16,21)) -> 25 | I16: =IF(A16="","",TEXT(A16,"[$-de-DE]MMMM YYYY")) -> Juni YYYY | J16: Projektplanung | K16: Initial | L16: =IF(A16="","",IF(Einstellungen!$B$15="","",MAX(0,MIN(E16,Einstellungen!$B$15-(SUMIFS($E$13:$E16,$H$13:$H16,H16)-E16))))) -> 0.5 | M16: =IF(A16="","",IF(L16="","",E16-L16)) -> 0 | N16: =IF(A16="","",SUMIFS($E$13:$E$214,$H$13:$H$214,H16)) -> 10.3 | O16: =IF(A16="","",IF(Einstellungen!$B$15="","",Einstellungen!$B$15-N16)) -> 9.7
A17: 46192 | B17: Asana / Monday | C17: Board- und Prozessanalyse | D17: Analyse vorhandener Monday-Boards und Prozesse mit Blick auf Migrationsrelevanz, Struktur, Dubletten und notwendige Übertragungslogik. Ergebnis: Identifiziert, was wirklich migriert werden muss und wo Prozessvereinfachung möglich ist, statt bestehende Komplexität ungeprüft nach Asana zu kopieren. | E17: 1.15 | F17: =IF(A17="","",Einstellungen!$B$5) -> 85 | G17: =IF(A17="","",L17*F17) -> 97.75 | H17: =IF(A17="","",WEEKNUM(A17,21)) -> 25 | I17: =IF(A17="","",TEXT(A17,"[$-de-DE]MMMM YYYY")) -> Juni YYYY | J17: Analyse / Recherche | K17: Initial | L17: =IF(A17="","",IF(Einstellungen!$B$15="","",MAX(0,MIN(E17,Einstellungen!$B$15-(SUMIFS($E$13:$E17,$H$13:$H17,H17)-E17))))) -> 1.15 | M17: =IF(A17="","",IF(L17="","",E17-L17)) -> 0 | N17: =IF(A17="","",SUMIFS($E$13:$E$214,$H$13:$H$214,H17)) -> 10.3 | O17: =IF(A17="","",IF(Einstellungen!$B$15="","",Einstellungen!$B$15-N17)) -> 9.7
A18: 46193 | B18: QR Code | C18: Toolvergleich und Build-Abgleich | D18: Detaillierte Analyse ausgewählter markttauglicher Tools und strukturierter Abgleich der Ergebnisse mit den Anforderungen an einen möglichen eigenen Build. Ergebnis: CMC_QR_Tool_Gegenueberstellung.xlsx mit Entscheidungsmatrix, Annahmen, Kurzfazit und nächsten Schritten; ergänzt durch Klarheit zum technischen Stack. | E18: 2.75 | F18: =IF(A18="","",Einstellungen!$B$5) -> 85 | G18: =IF(A18="","",L18*F18) -> 233.75 | H18: =IF(A18="","",WEEKNUM(A18,21)) -> 25 | I18: =IF(A18="","",TEXT(A18,"[$-de-DE]MMMM YYYY")) -> Juni YYYY | J18: Analyse / Recherche | K18: Abgeschlossen | L18: =IF(A18="","",IF(Einstellungen!$B$15="","",MAX(0,MIN(E18,Einstellungen!$B$15-(SUMIFS($E$13:$E18,$H$13:$H18,H18)-E18))))) -> 2.75 | M18: =IF(A18="","",IF(L18="","",E18-L18)) -> 0 | N18: =IF(A18="","",SUMIFS($E$13:$E$214,$H$13:$H$214,H18)) -> 10.3 | O18: =IF(A18="","",IF(Einstellungen!$B$15="","",Einstellungen!$B$15-N18)) -> 9.7
A19: 46194 | B19: QR Code | C19: Gegenüberstellung prüfen, ergänzen und aufbereiten | D19: Durchsicht der QR-Tool-Gegenüberstellung, Ergänzung offener Punkte und Aufbereitung der Inhalte für eine verständliche Entscheidungsgrundlage. Ergebnis: Die Gegenüberstellung ist für Robert klarer nutzbar: Bewertung, Annahmen, Risiken und nächste Schritte sind konsistenter herausgearbeitet. | E19: 0.5 | F19: =IF(A19="","",Einstellungen!$B$5) -> 85 | G19: =IF(A19="","",L19*F19) -> 42.5 | H19: =IF(A19="","",WEEKNUM(A19,21)) -> 25 | I19: =IF(A19="","",TEXT(A19,"[$-de-DE]MMMM YYYY")) -> Juni YYYY | J19: Analyse / Recherche | K19: Abgeschlossen | L19: =IF(A19="","",IF(Einstellungen!$B$15="","",MAX(0,MIN(E19,Einstellungen!$B$15-(SUMIFS($E$13:$E19,$H$13:$H19,H19)-E19))))) -> 0.5 | M19: =IF(A19="","",IF(L19="","",E19-L19)) -> 0 | N19: =IF(A19="","",SUMIFS($E$13:$E$214,$H$13:$H$214,H19)) -> 10.3 | O19: =IF(A19="","",IF(Einstellungen!$B$15="","",Einstellungen!$B$15-N19)) -> 9.7
A20: 46196 | B20: QR Code | C20: Leistungsbeschreibung Short.io-Anfrage | D20: Ausarbeitung einer strukturierten Leistungsbeschreibung für die geplante Short.io-Anfrage einschließlich fachlicher Anforderungen, relevanter Rahmenbedingungen und prüffähiger Anfrageinhalte als Grundlage für die weitere Anbieterabstimmung. | E20: 1.2 | F20: =IF(A20="","",Einstellungen!$B$5) -> 85 | G20: =IF(A20="","",L20*F20) -> 102 | H20: =IF(A20="","",WEEKNUM(A20,21)) -> 26 | I20: =IF(A20="","",TEXT(A20,"[$-de-DE]MMMM YYYY")) -> Juni YYYY | L20: =IF(A20="","",IF(Einstellungen!$B$15="","",MAX(0,MIN(E20,Einstellungen!$B$15-(SUMIFS($E$13:$E20,$H$13:$H20,H20)-E20))))) -> 1.2 | M20: =IF(A20="","",IF(L20="","",E20-L20)) -> 0 | N20: =IF(A20="","",SUMIFS($E$13:$E$214,$H$13:$H$214,H20)) -> 16 | O20: =IF(A20="","",IF(Einstellungen!$B$15="","",Einstellungen!$B$15-N20)) -> 4
A21: 46197 | B21: Studie 2027 | C21: Abstimmung Testvarianten Studienkonzept | D21: Abstimmung mit Jule, Simone und Cathleen zur Konzeption und Einordnung der vier vorgesehenen Testvarianten; Klärung zentraler Anforderungen, Variantenlogik und nächster Schritte für die weitere Studienplanung. | E21: 1 | F21: =IF(A21="","",Einstellungen!$B$5) -> 85 | G21: =IF(A21="","",L21*F21) -> 85 | H21: =IF(A21="","",WEEKNUM(A21,21)) -> 26 | I21: =IF(A21="","",TEXT(A21,"[$-de-DE]MMMM YYYY")) -> Juni YYYY | L21: =IF(A21="","",IF(Einstellungen!$B$15="","",MAX(0,MIN(E21,Einstellungen!$B$15-(SUMIFS($E$13:$E21,$H$13:$H21,H21)-E21))))) -> 1 | M21: =IF(A21="","",IF(L21="","",E21-L21)) -> 0 | N21: =IF(A21="","",SUMIFS($E$13:$E$214,$H$13:$H$214,H21)) -> 16 | O21: =IF(A21="","",IF(Einstellungen!$B$15="","",Einstellungen!$B$15-N21)) -> 4
A22: 46197 | B22: Studie 2027 | C22: Einarbeitung Methodik und Studienunterlagen | D22: Einarbeitung in das Studienthema, Recherche und fachliche Einordnung der verwendeten Methoden sowie Durcharbeitung der vorhandenen Präsentationsunterlagen zur Vorbereitung der weiteren konzeptionellen und inhaltlichen Ausarbeitung. | E22: 1.6 | F22: =IF(A22="","",Einstellungen!$B$5) -> 85 | G22: =IF(A22="","",L22*F22) -> 136 | H22: =IF(A22="","",WEEKNUM(A22,21)) -> 26 | I22: =IF(A22="","",TEXT(A22,"[$-de-DE]MMMM YYYY")) -> Juni YYYY | L22: =IF(A22="","",IF(Einstellungen!$B$15="","",MAX(0,MIN(E22,Einstellungen!$B$15-(SUMIFS($E$13:$E22,$H$13:$H22,H22)-E22))))) -> 1.6 | M22: =IF(A22="","",IF(L22="","",E22-L22)) -> 0 | N22: =IF(A22="","",SUMIFS($E$13:$E$214,$H$13:$H$214,H22)) -> 16 | O22: =IF(A22="","",IF(Einstellungen!$B$15="","",Einstellungen!$B$15-N22)) -> 4
A23: 46197 | B23: Studie 2027 | C23: Briefing Präsentationsausarbeitung | D23: Erstellung und Strukturierung eines Briefings für Cathleen zur weiteren Bearbeitung der Präsentation, inklusive Zusammenfassung relevanter Inhalte und Anforderungen für die nächste Ausarbeitungsschleife. | E23: 0.5 | F23: =IF(A23="","",Einstellungen!$B$5) -> 85 | G23: =IF(A23="","",L23*F23) -> 42.5 | H23: =IF(A23="","",WEEKNUM(A23,21)) -> 26 | I23: =IF(A23="","",TEXT(A23,"[$-de-DE]MMMM YYYY")) -> Juni YYYY | L23: =IF(A23="","",IF(Einstellungen!$B$15="","",MAX(0,MIN(E23,Einstellungen!$B$15-(SUMIFS($E$13:$E23,$H$13:$H23,H23)-E23))))) -> 0.5 | M23: =IF(A23="","",IF(L23="","",E23-L23)) -> 0 | N23: =IF(A23="","",SUMIFS($E$13:$E$214,$H$13:$H$214,H23)) -> 16 | O23: =IF(A23="","",IF(Einstellungen!$B$15="","",Einstellungen!$B$15-N23)) -> 4
A24: 46198 | B24: Studie 2027 | C24: Finalisierung Briefing und Visualisierungstexte | D24: Finalisierung des Briefings für Cathleen sowie Ausarbeitung und Präzisierung von Textvorschlägen und Visualisierungsansätzen für die Studienpräsentation. | E24: 1.2 | F24: =IF(A24="","",Einstellungen!$B$5) -> 85 | G24: =IF(A24="","",L24*F24) -> 102 | H24: =IF(A24="","",WEEKNUM(A24,21)) -> 26 | I24: =IF(A24="","",TEXT(A24,"[$-de-DE]MMMM YYYY")) -> Juni YYYY | L24: =IF(A24="","",IF(Einstellungen!$B$15="","",MAX(0,MIN(E24,Einstellungen!$B$15-(SUMIFS($E$13:$E24,$H$13:$H24,H24)-E24))))) -> 1.2 | M24: =IF(A24="","",IF(L24="","",E24-L24)) -> 0 | N24: =IF(A24="","",SUMIFS($E$13:$E$214,$H$13:$H$214,H24)) -> 16 | O24: =IF(A24="","",IF(Einstellungen!$B$15="","",Einstellungen!$B$15-N24)) -> 4
A25: 46198 | B25: Studie 2027 | C25: Anfrage POSTWURFSPEZIAL | D25: Vorbereitung und Formulierung der Anfrage zu POSTWURFSPEZIAL unter Berücksichtigung der für die Studienumsetzung relevanten Anforderungen und Abstimmungsbedarfe. | E25: 0.6 | F25: =IF(A25="","",Einstellungen!$B$5) -> 85 | G25: =IF(A25="","",L25*F25) -> 51 | H25: =IF(A25="","",WEEKNUM(A25,21)) -> 26 | I25: =IF(A25="","",TEXT(A25,"[$-de-DE]MMMM YYYY")) -> Juni YYYY | L25: =IF(A25="","",IF(Einstellungen!$B$15="","",MAX(0,MIN(E25,Einstellungen!$B$15-(SUMIFS($E$13:$E25,$H$13:$H25,H25)-E25))))) -> 0.6 | M25: =IF(A25="","",IF(L25="","",E25-L25)) -> 0 | N25: =IF(A25="","",SUMIFS($E$13:$E$214,$H$13:$H$214,H25)) -> 16 | O25: =IF(A25="","",IF(Einstellungen!$B$15="","",Einstellungen!$B$15-N25)) -> 4
A26: 46198 | B26: Studie 2027 | C26: Ist-/Soll-Analyse Studienmailing | D26: Durchführung einer Ist-/Soll-Analyse für die Erstellung des Studienmailings; Prüfung des Partnerfragebogens und der InDesign-Vorlagen sowie Bewertung möglicher Automatisierungsansätze einschließlich teambezogener Abstimmungen zu Umsetzbarkeit und Vorgehen. | E26: 2.15 | F26: =IF(A26="","",Einstellungen!$B$5) -> 85 | G26: =IF(A26="","",L26*F26) -> 182.75 | H26: =IF(A26="","",WEEKNUM(A26,21)) -> 26 | I26: =IF(A26="","",TEXT(A26,"[$-de-DE]MMMM YYYY")) -> Juni YYYY | L26: =IF(A26="","",IF(Einstellungen!$B$15="","",MAX(0,MIN(E26,Einstellungen!$B$15-(SUMIFS($E$13:$E26,$H$13:$H26,H26)-E26))))) -> 2.15 | M26: =IF(A26="","",IF(L26="","",E26-L26)) -> 0 | N26: =IF(A26="","",SUMIFS($E$13:$E$214,$H$13:$H$214,H26)) -> 16 | O26: =IF(A26="","",IF(Einstellungen!$B$15="","",Einstellungen!$B$15-N26)) -> 4
A27: 46198 | B27: Studie 2027 | C27: Klärung Pre-Test-Vorgehen | D27: Klärung des geplanten Pre-Test-Vorgehens mit dem Team, einschließlich Abstimmung offener Punkte und Einordnung der nächsten Schritte für die weitere Studienvorbereitung. | E27: 0.3 | F27: =IF(A27="","",Einstellungen!$B$5) -> 85 | G27: =IF(A27="","",L27*F27) -> 25.5 | H27: =IF(A27="","",WEEKNUM(A27,21)) -> 26 | I27: =IF(A27="","",TEXT(A27,"[$-de-DE]MMMM YYYY")) -> Juni YYYY | L27: =IF(A27="","",IF(Einstellungen!$B$15="","",MAX(0,MIN(E27,Einstellungen!$B$15-(SUMIFS($E$13:$E27,$H$13:$H27,H27)-E27))))) -> 0.3 | M27: =IF(A27="","",IF(L27="","",E27-L27)) -> 0 | N27: =IF(A27="","",SUMIFS($E$13:$E$214,$H$13:$H$214,H27)) -> 16 | O27: =IF(A27="","",IF(Einstellungen!$B$15="","",Einstellungen!$B$15-N27)) -> 4
A28: 46198 | B28: Studie 2027 | C28: Statusabfrage und Arbeitspaket-Update | D28: Einholung aktueller Statusinformationen und Aktualisierung der Arbeitspakete bis zum 03.07.; Strukturierung der offenen Punkte und Nachverfolgung relevanter Zuständigkeiten. | E28: 0.5 | F28: =IF(A28="","",Einstellungen!$B$5) -> 85 | G28: =IF(A28="","",L28*F28) -> 42.5 | H28: =IF(A28="","",WEEKNUM(A28,21)) -> 26 | I28: =IF(A28="","",TEXT(A28,"[$-de-DE]MMMM YYYY")) -> Juni YYYY | L28: =IF(A28="","",IF(Einstellungen!$B$15="","",MAX(0,MIN(E28,Einstellungen!$B$15-(SUMIFS($E$13:$E28,$H$13:$H28,H28)-E28))))) -> 0.5 | M28: =IF(A28="","",IF(L28="","",E28-L28)) -> 0 | N28: =IF(A28="","",SUMIFS($E$13:$E$214,$H$13:$H$214,H28)) -> 16 | O28: =IF(A28="","",IF(Einstellungen!$B$15="","",Einstellungen!$B$15-N28)) -> 4
A29: 46199 | B29: Studie 2027 | C29: Testskript und Zusammenfassung | D29: Erstellung eines Skripts und Zusammenfassung der Inhalte als Testfassung für Jule und Simone, einschließlich Aufbereitung der relevanten Punkte für Prüfung, Feedback und weitere Abstimmung. | E29: 1.55 | F29: =IF(A29="","",Einstellungen!$B$5) -> 85 | G29: =IF(A29="","",L29*F29) -> 131.75 | H29: =IF(A29="","",WEEKNUM(A29,21)) -> 26 | I29: =IF(A29="","",TEXT(A29,"[$-de-DE]MMMM YYYY")) -> Juni YYYY | L29: =IF(A29="","",IF(Einstellungen!$B$15="","",MAX(0,MIN(E29,Einstellungen!$B$15-(SUMIFS($E$13:$E29,$H$13:$H29,H29)-E29))))) -> 1.55 | M29: =IF(A29="","",IF(L29="","",E29-L29)) -> 0 | N29: =IF(A29="","",SUMIFS($E$13:$E$214,$H$13:$H$214,H29)) -> 16 | O29: =IF(A29="","",IF(Einstellungen!$B$15="","",Einstellungen!$B$15-N29)) -> 4
A30: 46199 | B30: Studie 2027 | C30: Vor-/Nachbereitung Christina-Abstimmung | D30: Vor- und Nachbereitung der Abstimmung mit Christina einschließlich Terminabgleich, Strukturierung relevanter Inhalte und Ableitung der nächsten Schritte für die weitere Studien- und Präsentationsarbeit. | E30: 1.1 | F30: =IF(A30="","",Einstellungen!$B$5) -> 85 | G30: =IF(A30="","",L30*F30) -> 93.5 | H30: =IF(A30="","",WEEKNUM(A30,21)) -> 26 | I30: =IF(A30="","",TEXT(A30,"[$-de-DE]MMMM YYYY")) -> Juni YYYY | L30: =IF(A30="","",IF(Einstellungen!$B$15="","",MAX(0,MIN(E30,Einstellungen!$B$15-(SUMIFS($E$13:$E30,$H$13:$H30,H30)-E30))))) -> 1.1 | M30: =IF(A30="","",IF(L30="","",E30-L30)) -> 0 | N30: =IF(A30="","",SUMIFS($E$13:$E$214,$H$13:$H$214,H30)) -> 16 | O30: =IF(A30="","",IF(Einstellungen!$B$15="","",Einstellungen!$B$15-N30)) -> 4
A31: 46199 | B31: Studie 2027 | C31: Pre-Test-Abstimmung Lone/Lisa | D31: Abstimmung mit Lone und Lisa zum Pre-Test sowie zum Stand der bis Freitag vorgesehenen To-dos; Klärung offener Punkte, Zuständigkeiten und nächster Schritte. | E31: 0.7 | F31: =IF(A31="","",Einstellungen!$B$5) -> 85 | G31: =IF(A31="","",L31*F31) -> 59.5 | H31: =IF(A31="","",WEEKNUM(A31,21)) -> 26 | I31: =IF(A31="","",TEXT(A31,"[$-de-DE]MMMM YYYY")) -> Juni YYYY | L31: =IF(A31="","",IF(Einstellungen!$B$15="","",MAX(0,MIN(E31,Einstellungen!$B$15-(SUMIFS($E$13:$E31,$H$13:$H31,H31)-E31))))) -> 0.7 | M31: =IF(A31="","",IF(L31="","",E31-L31)) -> 0 | N31: =IF(A31="","",SUMIFS($E$13:$E$214,$H$13:$H$214,H31)) -> 16 | O31: =IF(A31="","",IF(Einstellungen!$B$15="","",Einstellungen!$B$15-N31)) -> 4
... A42: 46203 | B42: Studie 2027 | C42: Review und Weitergabe Präsentation | D42: Review der von Cathleen überarbeiteten Präsentation; Prüfung der inhaltlichen Anpassungen und Weitergabe relevanter Rückmeldungen für die weitere Bearbeitung. | E42: 0.6 | F42: =IF(A42="","",Einstellungen!$B$5) -> 85 | G42: =IF(A42="","",L42*F42) -> 51 | H42: =IF(A42="","",WEEKNUM(A42,21)) -> 27 | I42: =IF(A42="","",TEXT(A42,"[$-de-DE]MMMM YYYY")) -> Juni YYYY | L42: =IF(A42="","",IF(Einstellungen!$B$15="","",MAX(0,MIN(E42,Einstellungen!$B$15-(SUMIFS($E$13:$E42,$H$13:$H42,H42)-E42))))) -> 0.6 | M42: =IF(A42="","",IF(L42="","",E42-L42)) -> 0 | N42: =IF(A42="","",SUMIFS($E$13:$E$214,$H$13:$H$214,H42)) -> 19.85 | O42: =IF(A42="","",IF(Einstellungen!$B$15="","",Einstellungen!$B$15-N42)) -> 0.15
A43: 46204 | B43: Studie 2027 | D43: Auswertung Test A Variante + Anpassung Kript + Absprachen und Statusupdate | E43: 2.75 | F43: =IF(A43="","",Einstellungen!$B$5) -> 85 | G43: =IF(A43="","",L43*F43) -> 233.75 | H43: =IF(A43="","",WEEKNUM(A43,21)) -> 27 | I43: =IF(A43="","",TEXT(A43,"[$-de-DE]MMMM YYYY")) -> Juli YYYY | L43: =IF(A43="","",IF(Einstellungen!$B$15="","",MAX(0,MIN(E43,Einstellungen!$B$15-(SUMIFS($E$13:$E43,$H$13:$H43,H43)-E43))))) -> 2.75 | M43: =IF(A43="","",IF(L43="","",E43-L43)) -> 0 | N43: =IF(A43="","",SUMIFS($E$13:$E$214,$H$13:$H$214,H43)) -> 19.85 | O43: =IF(A43="","",IF(Einstellungen!$B$15="","",Einstellungen!$B$15-N43)) -> 0.15
A44: 46205 | B44: Studie 2027 | D44: Anpassung des Skriptes anhand der Variablen Liste für alle 4 Varianten + Anpassung, dass Bilder eingelesen und eingespielt werden + Definition und Kommunikation des nächsten Test für alle 4 Varianten | E44: 2.15 | F44: =IF(A44="","",Einstellungen!$B$5) -> 85 | G44: =IF(A44="","",L44*F44) -> 182.75 | H44: =IF(A44="","",WEEKNUM(A44,21)) -> 27 | I44: =IF(A44="","",TEXT(A44,"[$-de-DE]MMMM YYYY")) -> Juli YYYY | L44: =IF(A44="","",IF(Einstellungen!$B$15="","",MAX(0,MIN(E44,Einstellungen!$B$15-(SUMIFS($E$13:$E44,$H$13:$H44,H44)-E44))))) -> 2.15 | M44: =IF(A44="","",IF(L44="","",E44-L44)) -> 0 | N44: =IF(A44="","",SUMIFS($E$13:$E$214,$H$13:$H$214,H44)) -> 19.85 | O44: =IF(A44="","",IF(Einstellungen!$B$15="","",Einstellungen!$B$15-N44)) -> 0.15
A45: 46205 | B45: Studie 2027 | D45: Vorbereitung Ende zu Ende Test für Shabe Labs mit aufbereitung der Daten, Erstellen des Skriptes und Definiton der Testmessung | E45: 1.5 | F45: =IF(A45="","",Einstellungen!$B$5) -> 85 | G45: =IF(A45="","",L45*F45) -> 127.5 | H45: =IF(A45="","",WEEKNUM(A45,21)) -> 27 | I45: =IF(A45="","",TEXT(A45,"[$-de-DE]MMMM YYYY")) -> Juli YYYY | L45: =IF(A45="","",IF(Einstellungen!$B$15="","",MAX(0,MIN(E45,Einstellungen!$B$15-(SUMIFS($E$13:$E45,$H$13:$H45,H45)-E45))))) -> 1.5 | M45: =IF(A45="","",IF(L45="","",E45-L45)) -> 0 | N45: =IF(A45="","",SUMIFS($E$13:$E$214,$H$13:$H$214,H45)) -> 19.85 | O45: =IF(A45="","",IF(Einstellungen!$B$15="","",Einstellungen!$B$15-N45)) -> 0.15
A46: 46206 | B46: Studie 2027 | D46: Absprache Simone Durchführung End zu Ende Test | E46: 0.25 | F46: =IF(A46="","",Einstellungen!$B$5) -> 85 | G46: =IF(A46="","",L46*F46) -> 21.25 | H46: =IF(A46="","",WEEKNUM(A46,21)) -> 27 | I46: =IF(A46="","",TEXT(A46,"[$-de-DE]MMMM YYYY")) -> Juli YYYY | L46: =IF(A46="","",IF(Einstellungen!$B$15="","",MAX(0,MIN(E46,Einstellungen!$B$15-(SUMIFS($E$13:$E46,$H$13:$H46,H46)-E46))))) -> 0.25 | M46: =IF(A46="","",IF(L46="","",E46-L46)) -> 0 | N46: =IF(A46="","",SUMIFS($E$13:$E$214,$H$13:$H$214,H46)) -> 19.85 | O46: =IF(A46="","",IF(Einstellungen!$B$15="","",Einstellungen!$B$15-N46)) -> 0.15
A47: 46206 | B47: Studie 2027 | D47: Auswertung erneuter Skripttest + Anpassung Skript für Test 2 alle Varianten mit Vorder und Rückseite | E47: 1.15 | F47: =IF(A47="","",Einstellungen!$B$5) -> 85 | G47: =IF(A47="","",L47*F47) -> 97.75 | H47: =IF(A47="","",WEEKNUM(A47,21)) -> 27 | I47: =IF(A47="","",TEXT(A47,"[$-de-DE]MMMM YYYY")) -> Juli YYYY | L47: =IF(A47="","",IF(Einstellungen!$B$15="","",MAX(0,MIN(E47,Einstellungen!$B$15-(SUMIFS($E$13:$E47,$H$13:$H47,H47)-E47))))) -> 1.15 | M47: =IF(A47="","",IF(L47="","",E47-L47)) -> 0 | N47: =IF(A47="","",SUMIFS($E$13:$E$214,$H$13:$H$214,H47)) -> 19.85 | O47: =IF(A47="","",IF(Einstellungen!$B$15="","",Einstellungen!$B$15-N47)) -> 0.15
A48: 46206 | B48: Studie 2027 | D48: Auswertung erneuter Skripttest 2 + Anpassung Skript + Anpassung Shape Labs Testpaket | E48: 1.3 | F48: =IF(A48="","",Einstellungen!$B$5) -> 85 | G48: =IF(A48="","",L48*F48) -> 110.5 | H48: =IF(A48="","",WEEKNUM(A48,21)) -> 27 | I48: =IF(A48="","",TEXT(A48,"[$-de-DE]MMMM YYYY")) -> Juli YYYY | L48: =IF(A48="","",IF(Einstellungen!$B$15="","",MAX(0,MIN(E48,Einstellungen!$B$15-(SUMIFS($E$13:$E48,$H$13:$H48,H48)-E48))))) -> 1.3 | M48: =IF(A48="","",IF(L48="","",E48-L48)) -> 0 | N48: =IF(A48="","",SUMIFS($E$13:$E$214,$H$13:$H$214,H48)) -> 19.85 | O48: =IF(A48="","",IF(Einstellungen!$B$15="","",Einstellungen!$B$15-N48)) -> 0.15
A49: 46206 | B49: Studie 2027 | D49: Begleitung End zu Ende Test mit Auswertung des Standes und Statusupdate | E49: 1.4 | F49: =IF(A49="","",Einstellungen!$B$5) -> 85 | G49: =IF(A49="","",L49*F49) -> 119 | H49: =IF(A49="","",WEEKNUM(A49,21)) -> 27 | I49: =IF(A49="","",TEXT(A49,"[$-de-DE]MMMM YYYY")) -> Juli YYYY | L49: =IF(A49="","",IF(Einstellungen!$B$15="","",MAX(0,MIN(E49,Einstellungen!$B$15-(SUMIFS($E$13:$E49,$H$13:$H49,H49)-E49))))) -> 1.4 | M49: =IF(A49="","",IF(L49="","",E49-L49)) -> 0 | N49: =IF(A49="","",SUMIFS($E$13:$E$214,$H$13:$H$214,H49)) -> 19.85 | O49: =IF(A49="","",IF(Einstellungen!$B$15="","",Einstellungen!$B$15-N49)) -> 0.15
A50: 46209 | B50: Studie 2027 | D50: Studie 2027: Debrief mit Simone und Jule zum bisherigen Teststand; Sammlung offener Punkte und Einordnung der nächsten Arbeitsschritte. | E50: 1 | F50: =IF(A50="","",Einstellungen!$B$5) -> 85 | G50: =IF(A50="","",L50*F50) -> 85 | H50: =IF(A50="","",WEEKNUM(A50,21)) -> 28 | I50: =IF(A50="","",TEXT(A50,"[$-de-DE]MMMM YYYY")) -> Juli YYYY | L50: =IF(A50="","",IF(Einstellungen!$B$15="","",MAX(0,MIN(E50,Einstellungen!$B$15-(SUMIFS($E$13:$E50,$H$13:$H50,H50)-E50))))) -> 1 | M50: =IF(A50="","",IF(L50="","",E50-L50)) -> 0 | N50: =IF(A50="","",SUMIFS($E$13:$E$214,$H$13:$H$214,H50)) -> 21.55 | O50: =IF(A50="","",IF(Einstellungen!$B$15="","",Einstellungen!$B$15-N50)) -> -1.55
A51: 46209 | B51: Studie 2027 | D51: Studie 2027: Erstellung eines neuen Testpakets auf Basis des Debriefings sowie Weiterentwicklung des JSON-Builder-Tools für Jule und Simone, inklusive Prüfchecks und E-Mail-Output. | E51: 3.4 | F51: =IF(A51="","",Einstellungen!$B$5) -> 85 | G51: =IF(A51="","",L51*F51) -> 289 | H51: =IF(A51="","",WEEKNUM(A51,21)) -> 28 | I51: =IF(A51="","",TEXT(A51,"[$-de-DE]MMMM YYYY")) -> Juli YYYY | L51: =IF(A51="","",IF(Einstellungen!$B$15="","",MAX(0,MIN(E51,Einstellungen!$B$15-(SUMIFS($E$13:$E51,$H$13:$H51,H51)-E51))))) -> 3.4 | M51: =IF(A51="","",IF(L51="","",E51-L51)) -> 0 | N51: =IF(A51="","",SUMIFS($E$13:$E$214,$H$13:$H$214,H51)) -> 21.55 | O51: =IF(A51="","",IF(Einstellungen!$B$15="","",Einstellungen!$B$15-N51)) -> -1.55
A52: 46210 | B52: Studie 2027 | D52: Studie 2027: Kommunikation der nächsten Schritte an Jule und Simone, Auswertung der Testlaufzeiten sowie Aufbereitung eines Status-Updates zur Studie 2027. | E52: 1.45 | F52: =IF(A52="","",Einstellungen!$B$5) -> 85 | G52: =IF(A52="","",L52*F52) -> 123.25 | H52: =IF(A52="","",WEEKNUM(A52,21)) -> 28 | I52: =IF(A52="","",TEXT(A52,"[$-de-DE]MMMM YYYY")) -> Juli YYYY | L52: =IF(A52="","",IF(Einstellungen!$B$15="","",MAX(0,MIN(E52,Einstellungen!$B$15-(SUMIFS($E$13:$E52,$H$13:$H52,H52)-E52))))) -> 1.45 | M52: =IF(A52="","",IF(L52="","",E52-L52)) -> 0 | N52: =IF(A52="","",SUMIFS($E$13:$E$214,$H$13:$H$214,H52)) -> 21.55 | O52: =IF(A52="","",IF(Einstellungen!$B$15="","",Einstellungen!$B$15-N52)) -> -1.55
A53: 46210 | B53: Studie 2027 | D53: Studie 2027: Weiterentwicklung des JSON-Builder-Tools einschließlich Fehlerbehebung, zusätzlicher Prüfungen und optischer Optimierung; weitere Skriptoptimierung und Vorbereitung einer neuen Testrunde. | E53: 2.75 | F53: =IF(A53="","",Einstellungen!$B$5) -> 85 | G53: =IF(A53="","",L53*F53) -> 233.75 | H53: =IF(A53="","",WEEKNUM(A53,21)) -> 28 | I53: =IF(A53="","",TEXT(A53,"[$-de-DE]MMMM YYYY")) -> Juli YYYY | L53: =IF(A53="","",IF(Einstellungen!$B$15="","",MAX(0,MIN(E53,Einstellungen!$B$15-(SUMIFS($E$13:$E53,$H$13:$H53,H53)-E53))))) -> 2.75 | M53: =IF(A53="","",IF(L53="","",E53-L53)) -> 0 | N53: =IF(A53="","",SUMIFS($E$13:$E$214,$H$13:$H$214,H53)) -> 21.55 | O53: =IF(A53="","",IF(Einstellungen!$B$15="","",Einstellungen!$B$15-N53)) -> -1.55
A54: 46211 | B54: Studie 2027 | D54: Studie 2027: Auswertung des JSON-Builder- und Bildertests, Einarbeitung weiterer Anmerkungen sowie Zusammenstellung eines Testpakets für Simone. | E54: 1.1 | F54: =IF(A54="","",Einstellungen!$B$5) -> 85 | G54: =IF(A54="","",L54*F54) -> 93.5 | H54: =IF(A54="","",WEEKNUM(A54,21)) -> 28 | I54: =IF(A54="","",TEXT(A54,"[$-de-DE]MMMM YYYY")) -> Juli YYYY | L54: =IF(A54="","",IF(Einstellungen!$B$15="","",MAX(0,MIN(E54,Einstellungen!$B$15-(SUMIFS($E$13:$E54,$H$13:$H54,H54)-E54))))) -> 1.1 | M54: =IF(A54="","",IF(L54="","",E54-L54)) -> 0 | N54: =IF(A54="","",SUMIFS($E$13:$E$214,$H$13:$H$214,H54)) -> 21.55 | O54: =IF(A54="","",IF(Einstellungen!$B$15="","",Einstellungen!$B$15-N54)) -> -1.55
... A65: 46216 | B65: Studie 2027 | D65: Vorbereitung Weekly, aktueller Stand etc und Einarbeitung OKRs | E65: 1.25 | F65: =IF(A65="","",Einstellungen!$B$5) -> 85 | G65: =IF(A65="","",L65*F65) -> 106.25 | H65: =IF(A65="","",WEEKNUM(A65,21)) -> 29 | I65: =IF(A65="","",TEXT(A65,"[$-de-DE]MMMM YYYY")) -> Juli YYYY | L65: =IF(A65="","",IF(Einstellungen!$B$15="","",MAX(0,MIN(E65,Einstellungen!$B$15-(SUMIFS($E$13:$E65,$H$13:$H65,H65)-E65))))) -> 1.25 | M65: =IF(A65="","",IF(L65="","",E65-L65)) -> 0 | N65: =IF(A65="","",SUMIFS($E$13:$E$214,$H$13:$H$214,H65)) -> 23 | O65: =IF(A65="","",IF(Einstellungen!$B$15="","",Einstellungen!$B$15-N65)) -> -3
A66: 46216 | B66: Studie 2027 | D66: Weekly Team Meeting | E66: 1.5 | F66: =IF(A66="","",Einstellungen!$B$5) -> 85 | G66: =IF(A66="","",L66*F66) -> 127.5 | H66: =IF(A66="","",WEEKNUM(A66,21)) -> 29 | L66: =IF(A66="","",IF(Einstellungen!$B$15="","",MAX(0,MIN(E66,Einstellungen!$B$15-(SUMIFS($E$13:$E66,$H$13:$H66,H66)-E66))))) -> 1.5 | M66: =IF(A66="","",IF(L66="","",E66-L66)) -> 0 | N66: =IF(A66="","",SUMIFS($E$13:$E$214,$H$13:$H$214,H66)) -> 23 | O66: =IF(A66="","",IF(Einstellungen!$B$15="","",Einstellungen!$B$15-N66)) -> -3
...

Sheet Auswertung
A1: Auswertung
A2: Kurzer Plausibilitätscheck und Monatsübersicht aus der Zeiterfassung.
A4: Monat | B4: =Einstellungen!F5 -> Juni 2026 | D4: Kategorie | E4: Stunden | F4: Anteil
A5: Gesamtstunden | B5: =Datenbasis!D5 -> 35.65 | D5: Analyse / Recherche | E5: =SUMIFS(Datenbasis!$E$13:$E$214,Datenbasis!$J$13:$J$214,D5,Datenbasis!$A$13:$A$214,">="&Einstellungen!$B$4,Datenbasis!$A$13:$A$214,"<"&DATE(YEAR(Einstellungen!$B$4),MONTH(Einstellungen!$B$4)+1,1)) -> 7.55 | F5: =IF($B$5=0,0,E5/$B$5) -> 0.21178121
A6: Betrag | B6: =Datenbasis!E5 -> 3030.25 | D6: Technische Konzeption | E6: =SUMIFS(Datenbasis!$E$13:$E$214,Datenbasis!$J$13:$J$214,D6,Datenbasis!$A$13:$A$214,">="&Einstellungen!$B$4,Datenbasis!$A$13:$A$214,"<"&DATE(YEAR(Einstellungen!$B$4),MONTH(Einstellungen!$B$4)+1,1)) -> 1.5 | F6: =IF($B$5=0,0,E6/$B$5) -> 0.042075736
D7: Projektplanung | E7: =SUMIFS(Datenbasis!$E$13:$E$214,Datenbasis!$J$13:$J$214,D7,Datenbasis!$A$13:$A$214,">="&Einstellungen!$B$4,Datenbasis!$A$13:$A$214,"<"&DATE(YEAR(Einstellungen!$B$4),MONTH(Einstellungen!$B$4)+1,1)) -> 0.5 | F7: =IF($B$5=0,0,E7/$B$5) -> 0.014025245
D8: Setup / Administration | E8: =SUMIFS(Datenbasis!$E$13:$E$214,Datenbasis!$J$13:$J$214,D8,Datenbasis!$A$13:$A$214,">="&Einstellungen!$B$4,Datenbasis!$A$13:$A$214,"<"&DATE(YEAR(Einstellungen!$B$4),MONTH(Einstellungen!$B$4)+1,1)) -> 0.75 | F8: =IF($B$5=0,0,E8/$B$5) -> 0.021037868
D9: Umsetzung / Dokumentation | E9: =SUMIFS(Datenbasis!$E$13:$E$214,Datenbasis!$J$13:$J$214,D9,Datenbasis!$A$13:$A$214,">="&Einstellungen!$B$4,Datenbasis!$A$13:$A$214,"<"&DATE(YEAR(Einstellungen!$B$4),MONTH(Einstellungen!$B$4)+1,1)) -> 0 | F9: =IF($B$5=0,0,E9/$B$5) -> 0
A11: Schonungslos ehrlicher Check
A12: Gesamteindruck | B12: 10,30 Stunden für Startwoche/Analysephase sind plausibel. Der QR-Code-Anteil ist durch ein konkretes Ergebnis belegt: CMC_QR_Tool_Gegenueberstellung.xlsx plus technische Stack-Klarheit.
A13: QR-Code-Anteil | B13: 7,90 Stunden QR-Code sind mit diesem Output gut begründbar: Entscheidungsmatrix, Eigenbau-vs.-Markttool-Abgleich, Volumenannahmen, Risiken, Kurzfazit, Ergänzungen und nächste Schritte sind verwertbarer Mehrwert.
A14: Asana/Monday | B14: 1,65 Stunden sind für eine echte Migration zu wenig, aber als erster Projektplan plus Sichtung plausibel. Bitte nicht als vollständige Migrationsanalyse verkaufen.
A15: Setup-Zeit | B15: 0,75 Stunden für Accounts/Mail ist normal und unkritisch, sollte aber nicht größer werden, wenn kein technisches Problem dahintersteht.
A16: Empfehlung | B16: Für künftige Einträge immer ein Ergebnis ergänzen: Entscheidung, verworfene Option, Nächstes To-do, Risiko oder Vereinfachung. Dann liest Robert Mehrwert statt nur Arbeitszeit.
A19: KW | B19: Stunden | C19: Betrag | D19: Hinweis
A20: 25 | B20: =SUMIFS(Datenbasis!$E$13:$E$214,Datenbasis!$H$13:$H$214,A20,Datenbasis!$A$13:$A$214,">="&Einstellungen!$B$4,Datenbasis!$A$13:$A$214,"<"&DATE(YEAR(Einstellungen!$B$4),MONTH(Einstellungen!$B$4)+1,1)) -> 10.3 | C20: =SUMIFS(Datenbasis!$G$13:$G$214,Datenbasis!$H$13:$H$214,A20,Datenbasis!$A$13:$A$214,">="&Einstellungen!$B$4,Datenbasis!$A$13:$A$214,"<"&DATE(YEAR(Einstellungen!$B$4),MONTH(Einstellungen!$B$4)+1,1)) -> 875.5 | D20: =IF(B20=0,"",IF(B20<2,"kleiner Block / Kontextaufbau",IF(B20>8,"hoher Wochenblock - Output sichtbar machen","plausibler Wochenblock"))) -> hoher Wochenblock - Output sichtbar machen
A21: 26 | B21: =SUMIFS(Datenbasis!$E$13:$E$214,Datenbasis!$H$13:$H$214,A21,Datenbasis!$A$13:$A$214,">="&Einstellungen!$B$4,Datenbasis!$A$13:$A$214,"<"&DATE(YEAR(Einstellungen!$B$4),MONTH(Einstellungen!$B$4)+1,1)) -> 16 | C21: =SUMIFS(Datenbasis!$G$13:$G$214,Datenbasis!$H$13:$H$214,A21,Datenbasis!$A$13:$A$214,">="&Einstellungen!$B$4,Datenbasis!$A$13:$A$214,"<"&DATE(YEAR(Einstellungen!$B$4),MONTH(Einstellungen!$B$4)+1,1)) -> 1360 | D21: =IF(B21=0,"",IF(B21<2,"kleiner Block / Kontextaufbau",IF(B21>8,"hoher Wochenblock - Output sichtbar machen","plausibler Wochenblock"))) -> hoher Wochenblock - Output sichtbar machen
A22: 27 | B22: =SUMIFS(Datenbasis!$E$13:$E$214,Datenbasis!$H$13:$H$214,A22,Datenbasis!$A$13:$A$214,">="&Einstellungen!$B$4,Datenbasis!$A$13:$A$214,"<"&DATE(YEAR(Einstellungen!$B$4),MONTH(Einstellungen!$B$4)+1,1)) -> 9.35 | C22: =SUMIFS(Datenbasis!$G$13:$G$214,Datenbasis!$H$13:$H$214,A22,Datenbasis!$A$13:$A$214,">="&Einstellungen!$B$4,Datenbasis!$A$13:$A$214,"<"&DATE(YEAR(Einstellungen!$B$4),MONTH(Einstellungen!$B$4)+1,1)) -> 794.75 | D22: =IF(B22=0,"",IF(B22<2,"kleiner Block / Kontextaufbau",IF(B22>8,"hoher Wochenblock - Output sichtbar machen","plausibler Wochenblock"))) -> hoher Wochenblock - Output sichtbar machen
A23: 28 | B23: =SUMIFS(Datenbasis!$E$13:$E$214,Datenbasis!$H$13:$H$214,A23,Datenbasis!$A$13:$A$214,">="&Einstellungen!$B$4,Datenbasis!$A$13:$A$214,"<"&DATE(YEAR(Einstellungen!$B$4),MONTH(Einstellungen!$B$4)+1,1)) -> 0 | C23: =SUMIFS(Datenbasis!$G$13:$G$214,Datenbasis!$H$13:$H$214,A23,Datenbasis!$A$13:$A$214,">="&Einstellungen!$B$4,Datenbasis!$A$13:$A$214,"<"&DATE(YEAR(Einstellungen!$B$4),MONTH(Einstellungen!$B$4)+1,1)) -> 0 | D23: =IF(B23=0,"",IF(B23<2,"kleiner Block / Kontextaufbau",IF(B23>8,"hoher Wochenblock - Output sichtbar machen","plausibler Wochenblock")))
A24: 29 | B24: =SUMIFS(Datenbasis!$E$13:$E$214,Datenbasis!$H$13:$H$214,A24,Datenbasis!$A$13:$A$214,">="&Einstellungen!$B$4,Datenbasis!$A$13:$A$214,"<"&DATE(YEAR(Einstellungen!$B$4),MONTH(Einstellungen!$B$4)+1,1)) -> 0 | C24: =SUMIFS(Datenbasis!$G$13:$G$214,Datenbasis!$H$13:$H$214,A24,Datenbasis!$A$13:$A$214,">="&Einstellungen!$B$4,Datenbasis!$A$13:$A$214,"<"&DATE(YEAR(Einstellungen!$B$4),MONTH(Einstellungen!$B$4)+1,1)) -> 0 | D24: =IF(B24=0,"",IF(B24<2,"kleiner Block / Kontextaufbau",IF(B24>8,"hoher Wochenblock - Output sichtbar machen","plausibler Wochenblock")))
A25: 30 | B25: =SUMIFS(Datenbasis!$E$13:$E$214,Datenbasis!$H$13:$H$214,A25,Datenbasis!$A$13:$A$214,">="&Einstellungen!$B$4,Datenbasis!$A$13:$A$214,"<"&DATE(YEAR(Einstellungen!$B$4),MONTH(Einstellungen!$B$4)+1,1)) -> 0 | C25: =SUMIFS(Datenbasis!$G$13:$G$214,Datenbasis!$H$13:$H$214,A25,Datenbasis!$A$13:$A$214,">="&Einstellungen!$B$4,Datenbasis!$A$13:$A$214,"<"&DATE(YEAR(Einstellungen!$B$4),MONTH(Einstellungen!$B$4)+1,1)) -> 0 | D25: =IF(B25=0,"",IF(B25<2,"kleiner Block / Kontextaufbau",IF(B25>8,"hoher Wochenblock - Output sichtbar machen","plausibler Wochenblock")))
A26: 31 | B26: =SUMIFS(Datenbasis!$E$13:$E$214,Datenbasis!$H$13:$H$214,A26,Datenbasis!$A$13:$A$214,">="&Einstellungen!$B$4,Datenbasis!$A$13:$A$214,"<"&DATE(YEAR(Einstellungen!$B$4),MONTH(Einstellungen!$B$4)+1,1)) -> 0 | C26: =SUMIFS(Datenbasis!$G$13:$G$214,Datenbasis!$H$13:$H$214,A26,Datenbasis!$A$13:$A$214,">="&Einstellungen!$B$4,Datenbasis!$A$13:$A$214,"<"&DATE(YEAR(Einstellungen!$B$4),MONTH(Einstellungen!$B$4)+1,1)) -> 0 | D26: =IF(B26=0,"",IF(B26<2,"kleiner Block / Kontextaufbau",IF(B26>8,"hoher Wochenblock - Output sichtbar machen","plausibler Wochenblock")))
A27: 32 | B27: =SUMIFS(Datenbasis!$E$13:$E$214,Datenbasis!$H$13:$H$214,A27,Datenbasis!$A$13:$A$214,">="&Einstellungen!$B$4,Datenbasis!$A$13:$A$214,"<"&DATE(YEAR(Einstellungen!$B$4),MONTH(Einstellungen!$B$4)+1,1)) -> 0 | C27: =SUMIFS(Datenbasis!$G$13:$G$214,Datenbasis!$H$13:$H$214,A27,Datenbasis!$A$13:$A$214,">="&Einstellungen!$B$4,Datenbasis!$A$13:$A$214,"<"&DATE(YEAR(Einstellungen!$B$4),MONTH(Einstellungen!$B$4)+1,1)) -> 0 | D27: =IF(B27=0,"",IF(B27<2,"kleiner Block / Kontextaufbau",IF(B27>8,"hoher Wochenblock - Output sichtbar machen","plausibler Wochenblock")))
A28: 33 | B28: =SUMIFS(Datenbasis!$E$13:$E$214,Datenbasis!$H$13:$H$214,A28,Datenbasis!$A$13:$A$214,">="&Einstellungen!$B$4,Datenbasis!$A$13:$A$214,"<"&DATE(YEAR(Einstellungen!$B$4),MONTH(Einstellungen!$B$4)+1,1)) -> 0 | C28: =SUMIFS(Datenbasis!$G$13:$G$214,Datenbasis!$H$13:$H$214,A28,Datenbasis!$A$13:$A$214,">="&Einstellungen!$B$4,Datenbasis!$A$13:$A$214,"<"&DATE(YEAR(Einstellungen!$B$4),MONTH(Einstellungen!$B$4)+1,1)) -> 0 | D28: =IF(B28=0,"",IF(B28<2,"kleiner Block / Kontextaufbau",IF(B28>8,"hoher Wochenblock - Output sichtbar machen","plausibler Wochenblock")))

Sheet Monatstätigkeitsschein
A1: Monatstätigkeitsschein
A2: Druck-/kopierfähige Version. Die Formulierungen sind nutzenorientiert, aber auf die erfassten Tätigkeiten begrenzt.
A4: Monat | B4: =Einstellungen!F5 -> Juni 2026 | C4: Auftraggeber | D4: =Einstellungen!B6 -> Robert | E4: Auftragnehmer/in | F4: =Einstellungen!B7 -> Maria
A5: Gesamtstunden | B5: 35,65 | C5: Stundensatz | D5: 85 | E5: Betrag | F5: 3.030,25 €
A6: Kurzfazit | B6: Im Juni 2026 lagen die Schwerpunkte auf QR-Code-Tool-/Build-Analyse, technischer Arbeitsfähigkeit, erster Asana/Monday-Migrationssichtung sowie der konzeptionellen und technischen Vorbereitung der CMC-Studie 2027 einschließlich Testvarianten, POSTWURFSPEZIAL-Abstimmungen und KI-/InDesign-Automatisierung.
A11: Datum | B11: Bereich | C11: Tätigkeit | D11: Zeit | E11: Status
A12: 17.06.2026 | B12: QR Code | C12: Prozess-Refresh, Toolmarkt und Build-Option: Einarbeitung in den bestehenden QR-Code-Prozess, Ableitung der Soll-Anforderungen an ein neues Tool, erste Marktanalyse geeigneter Anbieter sowie technische Machbarkeitsprüfung eines eigenen Builds. Ergebnis: Grundlage für die QR-Tool-Gegenüberstellung: Soll-Kriterien, Markt-/Eigenbau-Perspektive und erste technische Stack-Klarheit wurden herausgearbeitet. | D12: 3,15 | E12: Abgeschlossen
A13: 18.06.2026 | B13: Technisches Setup | C13: Accounts, Mail und Arbeitsumgebung: Einrichtung und Prüfung der benötigten Accounts/Mail-Zugänge sowie kurze Orientierung in vorhandenen technischen Unterlagen und Arbeitsständen. Ergebnis: Reduziert Reibung im Folgeprozess und stellt sicher, dass weitere Analyse/Umsetzung ohne Zugriffshürden starten kann. | D13: 0,75 | E13: Abgeschlossen
A14: 18.06.2026 | B14: QR Code | C14: Technisches Setup und Stack-Vorauswahl: Verfeinerung des technischen Setups, Recherche möglicher Stack-Varianten und Eingrenzung der sinnvollsten Tool-/Build-Richtung. Ergebnis: Verdichtet die offenen Optionen technisch: Stack-Richtung, Toolanforderungen und Build-Risiken wurden so geklärt, dass die Gegenüberstellung belastbarer wird. | D14: 1,50 | E14: Abgeschlossen
A15: 18.06.2026 | B15: Asana / Monday | C15: Projektplan Migration Monday zu Asana: Aufsetzen eines ersten Projektplan-Rahmens für die Ablösung von Monday durch Asana inklusive erster Sichtung der Asana Features. | D15: 0,50 | E15: Initial
A16: 19.06.2026 | B16: Asana / Monday | C16: Board- und Prozessanalyse: Analyse vorhandener Monday-Boards und Prozesse mit Blick auf Migrationsrelevanz, Struktur, Dubletten und notwendige Übertragungslogik. Ergebnis: Identifiziert, was wirklich migriert werden muss und wo Prozessvereinfachung möglich ist, statt bestehende Komplexität ungeprüft nach Asana zu kopieren. | D16: 1,15 | E16: Initial
A17: 20.06.2026 | B17: QR Code | C17: Toolvergleich und Build-Abgleich: Detaillierte Analyse ausgewählter markttauglicher Tools und strukturierter Abgleich der Ergebnisse mit den Anforderungen an einen möglichen eigenen Build. Ergebnis: CMC_QR_Tool_Gegenueberstellung.xlsx mit Entscheidungsmatrix, Annahmen, Kurzfazit und nächsten Schritten; ergänzt durch Klarheit zum technischen Stack. | D17: 2,75 | E17: Abgeschlossen
A18: 21.06.2026 | B18: QR Code | C18: Gegenüberstellung prüfen, ergänzen und aufbereiten: Durchsicht der QR-Tool-Gegenüberstellung, Ergänzung offener Punkte und Aufbereitung der Inhalte für eine verständliche Entscheidungsgrundlage. Ergebnis: Die Gegenüberstellung ist für Robert klarer nutzbar: Bewertung, Annahmen, Risiken und nächste Schritte sind konsistenter herausgearbeitet. | D18: 0,50 | E18: Abgeschlossen
A19: 23.06.2026 | B19: QR Code | C19: Leistungsbeschreibung Short.io-Anfrage: Ausarbeitung einer strukturierten Leistungsbeschreibung für die geplante Short.io-Anfrage einschließlich fachlicher Anforderungen, relevanter Rahmenbedingungen und prüffähiger Anfrageinhalte als Grundlage für die weitere Anbieterabstimmung. | D19: 1,20
A20: 24.06.2026 | B20: Studie 2027 | C20: Abstimmung Testvarianten Studienkonzept: Abstimmung mit Jule, Simone und Cathleen zur Konzeption und Einordnung der vier vorgesehenen Testvarianten; Klärung zentraler Anforderungen, Variantenlogik und nächster Schritte für die weitere Studienplanung. | D20: 1,00
A21: 24.06.2026 | B21: Studie 2027 | C21: Einarbeitung Methodik und Studienunterlagen: Einarbeitung in das Studienthema, Recherche und fachliche Einordnung der verwendeten Methoden sowie Durcharbeitung der vorhandenen Präsentationsunterlagen zur Vorbereitung der weiteren konzeptionellen und inhaltlichen Ausarbeitung. | D21: 1,60
A22: 24.06.2026 | B22: Studie 2027 | C22: Briefing Präsentationsausarbeitung: Erstellung und Strukturierung eines Briefings für Cathleen zur weiteren Bearbeitung der Präsentation, inklusive Zusammenfassung relevanter Inhalte und Anforderungen für die nächste Ausarbeitungsschleife. | D22: 0,50
A23: 25.06.2026 | B23: Studie 2027 | C23: Finalisierung Briefing und Visualisierungstexte: Finalisierung des Briefings für Cathleen sowie Ausarbeitung und Präzisierung von Textvorschlägen und Visualisierungsansätzen für die Studienpräsentation. | D23: 1,20
A24: 25.06.2026 | B24: Studie 2027 | C24: Anfrage POSTWURFSPEZIAL: Vorbereitung und Formulierung der Anfrage zu POSTWURFSPEZIAL unter Berücksichtigung der für die Studienumsetzung relevanten Anforderungen und Abstimmungsbedarfe. | D24: 0,60
A25: 25.06.2026 | B25: Studie 2027 | C25: Ist-/Soll-Analyse Studienmailing: Durchführung einer Ist-/Soll-Analyse für die Erstellung des Studienmailings; Prüfung des Partnerfragebogens und der InDesign-Vorlagen sowie Bewertung möglicher Automatisierungsansätze einschließlich teambezogener Abstimmungen zu Umsetzbarkeit und Vorgehen. | D25: 2,15
A26: 25.06.2026 | B26: Studie 2027 | C26: Klärung Pre-Test-Vorgehen: Klärung des geplanten Pre-Test-Vorgehens mit dem Team, einschließlich Abstimmung offener Punkte und Einordnung der nächsten Schritte für die weitere Studienvorbereitung. | D26: 0,30
A27: 25.06.2026 | B27: Studie 2027 | C27: Statusabfrage und Arbeitspaket-Update: Einholung aktueller Statusinformationen und Aktualisierung der Arbeitspakete bis zum 03.07.; Strukturierung der offenen Punkte und Nachverfolgung relevanter Zuständigkeiten. | D27: 0,50
A28: 26.06.2026 | B28: Studie 2027 | C28: Testskript und Zusammenfassung: Erstellung eines Skripts und Zusammenfassung der Inhalte als Testfassung für Jule und Simone, einschließlich Aufbereitung der relevanten Punkte für Prüfung, Feedback und weitere Abstimmung. | D28: 1,55
